Workbook

Sheet POS_فاکتور
A1: CHAAM
A3: ───────────FJ COD───────────
A4: شماره فاکتور | B4: INV-0279 | D4: تاریخ | E4: 1405/07/19 | F4: شیفت | G4: full
A5: کد پرسنل | C5: =IFERROR(INDEX(اطلاعات_پرسنل!$D$4:$D$63,MATCH(B5,اطلاعات_پرسنل!$A$4:$A$63,0)),"کد یافت نشد") -> فروشگاه | F5: روش پرداخت | G5: کارت
A6: عضویت | D6: کانال | E6: حضوري | F6: پرداخت شده | G6: 0 | I6: chaam
A7: ─────اطلاعات شما─────
A8: نام | D8: نام خانوادگی | F8: شماره تماس
A9: روز تولد | C9: ماه | E9: یادداشت
A10: ──────────────────────────
A11: # | B11: SKU | C11: بارکد | D11: نام محصول | E11: تعداد | F11: قیمت واحد | G11: تخفیف | H11: جمع ردیف
A12: 1 | D12: =IF(B12<>"",IFERROR(INDEX(کاتالوگ_محصولات!$C$4:$C$303,MATCH(B12,کاتالوگ_محصولات!$A$4:$A$303,0)),""),IF(C12<>"",IFERROR(INDEX(کاتالوگ_محصولات!$C$4:$C$303,MATCH(C12,کاتالوگ_محصولات!$B$4:$B$303,0)),IFERROR(INDEX(کاتالوگ_محصولات!$C$4:$C$303,MATCH(C12,کاتالوگ_محصولات!$C$4:$C$303,0)),"")),"")) | E12: 0 | F12: =IF(B12<>"",IFERROR(INDEX(کاتالوگ_محصولات!$H$4:$H$303,MATCH(B12,کاتالوگ_محصولات!$A$4:$A$303,0)),0),IF(C12<>"",IFERROR(INDEX(کاتالوگ_محصولات!$H$4:$H$303,MATCH(C12,کاتالوگ_محصولات!$B$4:$B$303,0)),IFERROR(INDEX(کاتالوگ_محصولات!$H$4:$H$303,MATCH(C12,کاتالوگ_محصولات!$C$4:$C$303,0)),0)),0)) -> 0 | G12: 0 | H12: =MAX(0,E12*F12-G12) -> 0
A13: 2 | D13: =IF(B13<>"",IFERROR(INDEX(کاتالوگ_محصولات!$C$4:$C$303,MATCH(B13,کاتالوگ_محصولات!$A$4:$A$303,0)),""),IF(C13<>"",IFERROR(INDEX(کاتالوگ_محصولات!$C$4:$C$303,MATCH(C13,کاتالوگ_محصولات!$B$4:$B$303,0)),IFERROR(INDEX(کاتالوگ_محصولات!$C$4:$C$303,MATCH(C13,کاتالوگ_محصولات!$C$4:$C$303,0)),"")),"")) | E13: 0 | F13: =IF(B13<>"",IFERROR(INDEX(کاتالوگ_محصولات!$H$4:$H$303,MATCH(B13,کاتالوگ_محصولات!$A$4:$A$303,0)),0),IF(C13<>"",IFERROR(INDEX(کاتالوگ_محصولات!$H$4:$H$303,MATCH(C13,کاتالوگ_محصولات!$B$4:$B$303,0)),IFERROR(INDEX(کاتالوگ_محصولات!$H$4:$H$303,MATCH(C13,کاتالوگ_محصولات!$C$4:$C$303,0)),0)),0)) -> 0 | G13: 0 | H13: =MAX(0,E13*F13-G13) -> 0
A14: 3 | D14: =IF(B14<>"",IFERROR(INDEX(کاتالوگ_محصولات!$C$4:$C$303,MATCH(B14,کاتالوگ_محصولات!$A$4:$A$303,0)),""),IF(C14<>"",IFERROR(INDEX(کاتالوگ_محصولات!$C$4:$C$303,MATCH(C14,کاتالوگ_محصولات!$B$4:$B$303,0)),IFERROR(INDEX(کاتالوگ_محصولات!$C$4:$C$303,MATCH(C14,کاتالوگ_محصولات!$C$4:$C$303,0)),"")),"")) | E14: 0 | F14: =IF(B14<>"",IFERROR(INDEX(کاتالوگ_محصولات!$H$4:$H$303,MATCH(B14,کاتالوگ_محصولات!$A$4:$A$303,0)),0),IF(C14<>"",IFERROR(INDEX(کاتالوگ_محصولات!$H$4:$H$303,MATCH(C14,کاتالوگ_محصولات!$B$4:$B$303,0)),IFERROR(INDEX(کاتالوگ_محصولات!$H$4:$H$303,MATCH(C14,کاتالوگ_محصولات!$C$4:$C$303,0)),0)),0)) -> 0 | G14: 0 | H14: =MAX(0,E14*F14-G14) -> 0
A15: 4 | D15: =IF(B15<>"",IFERROR(INDEX(کاتالوگ_محصولات!$C$4:$C$303,MATCH(B15,کاتالوگ_محصولات!$A$4:$A$303,0)),""),IF(C15<>"",IFERROR(INDEX(کاتالوگ_محصولات!$C$4:$C$303,MATCH(C15,کاتالوگ_محصولات!$B$4:$B$303,0)),IFERROR(INDEX(کاتالوگ_محصولات!$C$4:$C$303,MATCH(C15,کاتالوگ_محصولات!$C$4:$C$303,0)),"")),"")) | E15: 0 | F15: =IF(B15<>"",IFERROR(INDEX(کاتالوگ_محصولات!$H$4:$H$303,MATCH(B15,کاتالوگ_محصولات!$A$4:$A$303,0)),0),IF(C15<>"",IFERROR(INDEX(کاتالوگ_محصولات!$H$4:$H$303,MATCH(C15,کاتالوگ_محصولات!$B$4:$B$303,0)),IFERROR(INDEX(کاتالوگ_محصولات!$H$4:$H$303,MATCH(C15,کاتالوگ_محصولات!$C$4:$C$303,0)),0)),0)) -> 0 | G15: 0 | H15: =MAX(0,E15*F15-G15) -> 0
A16: 5 | D16: =IF(B16<>"",IFERROR(INDEX(کاتالوگ_محصولات!$C$4:$C$303,MATCH(B16,کاتالوگ_محصولات!$A$4:$A$303,0)),""),IF(C16<>"",IFERROR(INDEX(کاتالوگ_محصولات!$C$4:$C$303,MATCH(C16,کاتالوگ_محصولات!$B$4:$B$303,0)),IFERROR(INDEX(کاتالوگ_محصولات!$C$4:$C$303,MATCH(C16,کاتالوگ_محصولات!$C$4:$C$303,0)),"")),"")) | E16: 0 | F16: =IF(B16<>"",IFERROR(INDEX(کاتالوگ_محصولات!$H$4:$H$303,MATCH(B16,کاتالوگ_محصولات!$A$4:$A$303,0)),0),IF(C16<>"",IFERROR(INDEX(کاتالوگ_محصولات!$H$4:$H$303,MATCH(C16,کاتالوگ_محصولات!$B$4:$B$303,0)),IFERROR(INDEX(کاتالوگ_محصولات!$H$4:$H$303,MATCH(C16,کاتالوگ_محصولات!$C$4:$C$303,0)),0)),0)) -> 0 | G16: 0 | H16: =MAX(0,E16*F16-G16) -> 0
A17: 6 | D17: =IF(B17<>"",IFERROR(INDEX(کاتالوگ_محصولات!$C$4:$C$303,MATCH(B17,کاتالوگ_محصولات!$A$4:$A$303,0)),""),IF(C17<>"",IFERROR(INDEX(کاتالوگ_محصولات!$C$4:$C$303,MATCH(C17,کاتالوگ_محصولات!$B$4:$B$303,0)),IFERROR(INDEX(کاتالوگ_محصولات!$C$4:$C$303,MATCH(C17,کاتالوگ_محصولات!$C$4:$C$303,0)),"")),"")) | E17: 0 | F17: =IF(B17<>"",IFERROR(INDEX(کاتالوگ_محصولات!$H$4:$H$303,MATCH(B17,کاتالوگ_محصولات!$A$4:$A$303,0)),0),IF(C17<>"",IFERROR(INDEX(کاتالوگ_محصولات!$H$4:$H$303,MATCH(C17,کاتالوگ_محصولات!$B$4:$B$303,0)),IFERROR(INDEX(کاتالوگ_محصولات!$H$4:$H$303,MATCH(C17,کاتالوگ_محصولات!$C$4:$C$303,0)),0)),0)) -> 0 | G17: 0 | H17: =MAX(0,E17*F17-G17) -> 0
A18: 7 | D18: =IF(B18<>"",IFERROR(INDEX(کاتالوگ_محصولات!$C$4:$C$303,MATCH(B18,کاتالوگ_محصولات!$A$4:$A$303,0)),""),IF(C18<>"",IFERROR(INDEX(کاتالوگ_محصولات!$C$4:$C$303,MATCH(C18,کاتالوگ_محصولات!$B$4:$B$303,0)),IFERROR(INDEX(کاتالوگ_محصولات!$C$4:$C$303,MATCH(C18,کاتالوگ_محصولات!$C$4:$C$303,0)),"")),"")) | E18: 0 | F18: =IF(B18<>"",IFERROR(INDEX(کاتالوگ_محصولات!$H$4:$H$303,MATCH(B18,کاتالوگ_محصولات!$A$4:$A$303,0)),0),IF(C18<>"",IFERROR(INDEX(کاتالوگ_محصولات!$H$4:$H$303,MATCH(C18,کاتالوگ_محصولات!$B$4:$B$303,0)),IFERROR(INDEX(کاتالوگ_محصولات!$H$4:$H$303,MATCH(C18,کاتالوگ_محصولات!$C$4:$C$303,0)),0)),0)) -> 0 | G18: 0 | H18: =MAX(0,E18*F18-G18) -> 0
A19: 8 | D19: =IF(B19<>"",IFERROR(INDEX(کاتالوگ_محصولات!$C$4:$C$303,MATCH(B19,کاتالوگ_محصولات!$A$4:$A$303,0)),""),IF(C19<>"",IFERROR(INDEX(کاتالوگ_محصولات!$C$4:$C$303,MATCH(C19,کاتالوگ_محصولات!$B$4:$B$303,0)),IFERROR(INDEX(کاتالوگ_محصولات!$C$4:$C$303,MATCH(C19,کاتالوگ_محصولات!$C$4:$C$303,0)),"")),"")) | E19: 0 | F19: =IF(B19<>"",IFERROR(INDEX(کاتالوگ_محصولات!$H$4:$H$303,MATCH(B19,کاتالوگ_محصولات!$A$4:$A$303,0)),0),IF(C19<>"",IFERROR(INDEX(کاتالوگ_محصولات!$H$4:$H$303,MATCH(C19,کاتالوگ_محصولات!$B$4:$B$303,0)),IFERROR(INDEX(کاتالوگ_محصولات!$H$4:$H$303,MATCH(C19,کاتالوگ_محصولات!$C$4:$C$303,0)),0)),0)) -> 0 | G19: 0 | H19: =MAX(0,E19*F19-G19) -> 0
A20: 9 | D20: =IF(B20<>"",IFERROR(INDEX(کاتالوگ_محصولات!$C$4:$C$303,MATCH(B20,کاتالوگ_محصولات!$A$4:$A$303,0)),""),IF(C20<>"",IFERROR(INDEX(کاتالوگ_محصولات!$C$4:$C$303,MATCH(C20,کاتالوگ_محصولات!$B$4:$B$303,0)),IFERROR(INDEX(کاتالوگ_محصولات!$C$4:$C$303,MATCH(C20,کاتالوگ_محصولات!$C$4:$C$303,0)),"")),"")) | E20: 0 | F20: =IF(B20<>"",IFERROR(INDEX(کاتالوگ_محصولات!$H$4:$H$303,MATCH(B20,کاتالوگ_محصولات!$A$4:$A$303,0)),0),IF(C20<>"",IFERROR(INDEX(کاتالوگ_محصولات!$H$4:$H$303,MATCH(C20,کاتالوگ_محصولات!$B$4:$B$303,0)),IFERROR(INDEX(کاتالوگ_محصولات!$H$4:$H$303,MATCH(C20,کاتالوگ_محصولات!$C$4:$C$303,0)),0)),0)) -> 0 | G20: 0 | H20: =MAX(0,E20*F20-G20) -> 0
A21: 10 | D21: =IF(B21<>"",IFERROR(INDEX(کاتالوگ_محصولات!$C$4:$C$303,MATCH(B21,کاتالوگ_محصولات!$A$4:$A$303,0)),""),IF(C21<>"",IFERROR(INDEX(کاتالوگ_محصولات!$C$4:$C$303,MATCH(C21,کاتالوگ_محصولات!$B$4:$B$303,0)),IFERROR(INDEX(کاتالوگ_محصولات!$C$4:$C$303,MATCH(C21,کاتالوگ_محصولات!$C$4:$C$303,0)),"")),"")) | E21: 0 | F21: =IF(B21<>"",IFERROR(INDEX(کاتالوگ_محصولات!$H$4:$H$303,MATCH(B21,کاتالوگ_محصولات!$A$4:$A$303,0)),0),IF(C21<>"",IFERROR(INDEX(کاتالوگ_محصولات!$H$4:$H$303,MATCH(C21,کاتالوگ_محصولات!$B$4:$B$303,0)),IFERROR(INDEX(کاتالوگ_محصولات!$H$4:$H$303,MATCH(C21,کاتالوگ_محصولات!$C$4:$C$303,0)),0)),0)) -> 0 | G21: 0 | H21: =MAX(0,E21*F21-G21) -> 0
A22: ─────────────────────
A23: جمع قبل از تخفیف | E23: =SUMPRODUCT(E12:E21,F12:F21) -> 0
A24: تخفیف کل | E24: =SUM(G12:G21) -> 0
A25: مبلغ نهایی | E25: =MAX(0,E23-E24) -> 0
A26: تعداد اقلام | E26: =SUM(E12:E21) -> 0
A27: مانده (دریافتی - مبلغ) | E27: =IFERROR(G6-E25,0) -> 0
A29: 💛چام مدِ نجیب و امروزی زنانه💛
A30: insta: chaamofficial | chaamofficial.ir
A32: ▶ دکمه «ثبت فاکتور» را بزنید | Button «RegisterInvoice»
A33: 📋 بعد از ثبت، فاکتور پاک و شماره +۱ می‌شود | داده در «لاگ_فاکتور» ذخیره می‌شود

Sheet لاگ_فاکتور
A1: لاگ فاکتور
A2: شماره فاکتور Inv_No | B2: تاریخ Date | C2: کد پرسنل Staff_ID | D2: نام پرسنل Staff | E2: شیفت Shift | F2: روش پرداخت Payment | G2: نوع مشتری Cust_Type | H2: کانال Channel | I2: SKU | J2: بارکد/نام ورودی Product_Input | K2: نام کامل محصول Product_Name | L2: تعداد Qty | M2: قیمت واحد Unit_Price | N2: تخفیف Discount | O2: جمع ردیف Line_Total | P2: نام مشتری Cust_First | Q2: نام خانوادگی Cust_Last | R2: شماره تماس Phone | S2: روز تولد Birth_Day | T2: ماه تولد Birth_Month | U2: یادداشت Notes | V2: پرچم فاکتور | W2: فروش ناخالص ردیف | X2: کلید مشتری | Y2: مشتری جدید | Z2: فاکتور تکراری | AA2: مبلغ فاکتور | AB2: اقلام فاکتور | AC2: بهای تمام‌شده | AD2: حاشیه سود | AE2: ماه گزارش
A3: INV-0200 | B3: 1405/07/01 | C3: 0 | D3: فروشگاه | E3: full | F3: کارت | G3: جدید | H3: کانال | J3: کیف 4148 | K3: کیف 4148 | L3: 1 | M3: 2000000 | N3: 0 | O3: 2000000 | U3: خرید خانم صانعی | V3: =IF(A3="",0,IF(COUNTIF($A$3:A3,A3)=1,1,0)) -> 1 | W3: =IF(A3="",0,L3*M3) -> 2000000 | X3: =IF(R3<>"",R3,IF(AND(P3<>"",Q3<>""),P3&"|"&Q3,"")) | Y3: =IF(X3="",0,IF(COUNTIF($X$3:X3,X3)=1,1,0)) -> 0 | Z3: =IF(V3<>1,0,IF(X3="",0,IF(COUNTIF($X$2:X2,X3)>0,1,0))) -> 0 | AA3: =IF(V3=1,SUMIF($A$3:$A$1622,A3,$O$3:$O$1622),0) -> 2000000 | AB3: =IF(V3=1,SUMIF($A$3:$A$1622,A3,$L$3:$L$1622),0) -> 1 | AC3: =IF(I3="",0,L3*IFERROR(INDEX(کاتالوگ_محصولات!$G$4:$G$303,MATCH(I3,کاتالوگ_محصولات!$A$4:$A$303,0)),0)) -> 0 | AD3: =IF(A3="",0,O3-AC3) -> 2000000 | AE3: =IF(B3="","",LEFT(B3,7)) -> 1405/07
A4: INV-0201 | B4: 1405/07/02 | C4: 2 | D4: ماحی حمیدپور | E4: PM | F4: کارت | G4: جدید | H4: کانال | J4: شومیز لینن سونای سرمه ای 2 | K4: شومیز لینن سونای سرمه ای 2 | L4: 1 | M4: 1350000 | N4: 0 | O4: 1350000 | P4: نوشین | Q4: ایرانپور | R4: 9352269323 | S4: 14 | T4: 1360/01 | U4: پیوست فاکتور 195 | V4: =IF(A4="",0,IF(COUNTIF($A$3:A4,A4)=1,1,0)) -> 1 | W4: =IF(A4="",0,L4*M4) -> 1350000 | X4: =IF(R4<>"",R4,IF(AND(P4<>"",Q4<>""),P4&"|"&Q4,"")) -> 9352269323 | Y4: =IF(X4="",0,IF(COUNTIF($X$3:X4,X4)=1,1,0)) -> 1 | Z4: =IF(V4<>1,0,IF(X4="",0,IF(COUNTIF($X$3:X3,X4)>0,1,0))) -> 0 | AA4: =IF(V4=1,SUMIF($A$3:$A$1622,A4,$O$3:$O$1622),0) -> 1350000 | AB4: =IF(V4=1,SUMIF($A$3:$A$1622,A4,$L$3:$L$1622),0) -> 1 | AC4: =IF(I4="",0,L4*IFERROR(INDEX(کاتالوگ_محصولات!$G$4:$G$303,MATCH(I4,کاتالوگ_محصولات!$A$4:$A$303,0)),0)) -> 0 | AD4: =IF(A4="",0,O4-AC4) -> 1350000 | AE4: =IF(B4="","",LEFT(B4,7)) -> 1405/07
A5: INV-0202 | B5: 1405/07/02 | C5: 0 | D5: فروشگاه | E5: full | F5: کارت | G5: جدید | H5: کانال | J5: شومیز دریا کرم سایز1 | K5: شومیز دریا کرم سایز1 | L5: 1 | M5: 1980000 | N5: 0 | O5: 1980000 | P5: ساره | Q5: قدیانی | R5: 9129419189 | S5: 26 | T5: 1367/08 | V5: =IF(A5="",0,IF(COUNTIF($A$3:A5,A5)=1,1,0)) -> 1 | W5: =IF(A5="",0,L5*M5) -> 1980000 | X5: =IF(R5<>"",R5,IF(AND(P5<>"",Q5<>""),P5&"|"&Q5,"")) -> 9129419189 | Y5: =IF(X5="",0,IF(COUNTIF($X$3:X5,X5)=1,1,0)) -> 1 | Z5: =IF(V5<>1,0,IF(X5="",0,IF(COUNTIF($X$3:X4,X5)>0,1,0))) -> 0 | AA5: =IF(V5=1,SUMIF($A$3:$A$1622,A5,$O$3:$O$1622),0) -> 3960000 | AB5: =IF(V5=1,SUMIF($A$3:$A$1622,A5,$L$3:$L$1622),0) -> 2 | AC5: =IF(I5="",0,L5*IFERROR(INDEX(کاتالوگ_محصولات!$G$4:$G$303,MATCH(I5,کاتالوگ_محصولات!$A$4:$A$303,0)),0)) -> 0 | AD5: =IF(A5="",0,O5-AC5) -> 1980000 | AE5: =IF(B5="","",LEFT(B5,7)) -> 1405/07
A6: INV-0202 | B6: 1405/07/02 | C6: 0 | D6: فروشگاه | E6: full | F6: کارت | G6: جدید | H6: کانال | J6: شومیز دریا صورتی سایز1 | K6: شومیز دریا صورتی سایز1 | L6: 1 | M6: 1980000 | N6: 0 | O6: 1980000 | P6: ساره | Q6: قدیانی | R6: 9129419189 | S6: 26 | T6: 1367/08 | V6: =IF(A6="",0,IF(COUNTIF($A$3:A6,A6)=1,1,0)) -> 0 | W6: =IF(A6="",0,L6*M6) -> 1980000 | X6: =IF(R6<>"",R6,IF(AND(P6<>"",Q6<>""),P6&"|"&Q6,"")) -> 9129419189 | Y6: =IF(X6="",0,IF(COUNTIF($X$3:X6,X6)=1,1,0)) -> 0 | Z6: =IF(V6<>1,0,IF(X6="",0,IF(COUNTIF($X$3:X5,X6)>0,1,0))) -> 0 | AA6: =IF(V6=1,SUMIF($A$3:$A$1622,A6,$O$3:$O$1622),0) -> 0 | AB6: =IF(V6=1,SUMIF($A$3:$A$1622,A6,$L$3:$L$1622),0) -> 0 | AC6: =IF(I6="",0,L6*IFERROR(INDEX(کاتالوگ_محصولات!$G$4:$G$303,MATCH(I6,کاتالوگ_محصولات!$A$4:$A$303,0)),0)) -> 0 | AD6: =IF(A6="",0,O6-AC6) -> 1980000 | AE6: =IF(B6="","",LEFT(B6,7)) -> 1405/07
A7: INV-0203 | B7: 1405/07/02 | C7: 2 | D7: ماحی حمیدپور | E7: PM | F7: کارت | G7: جدید | H7: کانال | J7: شومیز ویولا سرخابی سایز1 | K7: شومیز ویولا سرخابی سایز1 | L7: 1 | M7: 2086000 | N7: 0 | O7: 2086000 | P7: دینا | Q7: پیمایی | R7: 9123871328 | S7: 24 | T7: 9 | V7: =IF(A7="",0,IF(COUNTIF($A$3:A7,A7)=1,1,0)) -> 1 | W7: =IF(A7="",0,L7*M7) -> 2086000 | X7: =IF(R7<>"",R7,IF(AND(P7<>"",Q7<>""),P7&"|"&Q7,"")) -> 9123871328 | Y7: =IF(X7="",0,IF(COUNTIF($X$3:X7,X7)=1,1,0)) -> 1 | Z7: =IF(V7<>1,0,IF(X7="",0,IF(COUNTIF($X$3:X6,X7)>0,1,0))) -> 0 | AA7: =IF(V7=1,SUMIF($A$3:$A$1622,A7,$O$3:$O$1622),0) -> 2086000 | AB7: =IF(V7=1,SUMIF($A$3:$A$1622,A7,$L$3:$L$1622),0) -> 1 | AC7: =IF(I7="",0,L7*IFERROR(INDEX(کاتالوگ_محصولات!$G$4:$G$303,MATCH(I7,کاتالوگ_محصولات!$A$4:$A$303,0)),0)) -> 0 | AD7: =IF(A7="",0,O7-AC7) -> 2086000 | AE7: =IF(B7="","",LEFT(B7,7)) -> 1405/07
A8: INV-0204 | B8: 1405/07/02 | C8: 2 | D8: ماحی حمیدپور | E8: PM | F8: کارت | G8: جدید | H8: کانال | J8: شومیز تایملس مشکی فری | K8: شومیز تایملس مشکی فری | L8: 1 | M8: 2200000 | N8: 0 | O8: 2200000 | P8: میترا | Q8: حشمتی | R8: 9194452406 | V8: =IF(A8="",0,IF(COUNTIF($A$3:A8,A8)=1,1,0)) -> 1 | W8: =IF(A8="",0,L8*M8) -> 2200000 | X8: =IF(R8<>"",R8,IF(AND(P8<>"",Q8<>""),P8&"|"&Q8,"")) -> 9194452406 | Y8: =IF(X8="",0,IF(COUNTIF($X$3:X8,X8)=1,1,0)) -> 1 | Z8: =IF(V8<>1,0,IF(X8="",0,IF(COUNTIF($X$3:X7,X8)>0,1,0))) -> 0 | AA8: =IF(V8=1,SUMIF($A$3:$A$1622,A8,$O$3:$O$1622),0) -> 2200000 | AB8: =IF(V8=1,SUMIF($A$3:$A$1622,A8,$L$3:$L$1622),0) -> 1 | AC8: =IF(I8="",0,L8*IFERROR(INDEX(کاتالوگ_محصولات!$G$4:$G$303,MATCH(I8,کاتالوگ_محصولات!$A$4:$A$303,0)),0)) -> 0 | AD8: =IF(A8="",0,O8-AC8) -> 2200000 | AE8: =IF(B8="","",LEFT(B8,7)) -> 1405/07
A9: INV-0205 | B9: 1405/07/03 | C9: 2 | D9: ماحی حمیدپور | E9: full | F9: اسنپ پی | G9: جدید | H9: کانال | J9: کت سبز | K9: کت سبز | L9: 1 | M9: 1800000 | N9: 0 | O9: 1800000 | P9: سمیرا | Q9: باجلان | R9: 9383159588 | S9: 2 | T9: 8 | U9: آپ سل 15 میلیونی | V9: =IF(A9="",0,IF(COUNTIF($A$3:A9,A9)=1,1,0)) -> 1 | W9: =IF(A9="",0,L9*M9) -> 1800000 | X9: =IF(R9<>"",R9,IF(AND(P9<>"",Q9<>""),P9&"|"&Q9,"")) -> 9383159588 | Y9: =IF(X9="",0,IF(COUNTIF($X$3:X9,X9)=1,1,0)) -> 1 | Z9: =IF(V9<>1,0,IF(X9="",0,IF(COUNTIF($X$3:X8,X9)>0,1,0))) -> 0 | AA9: =IF(V9=1,SUMIF($A$3:$A$1622,A9,$O$3:$O$1622),0) -> 13750000 | AB9: =IF(V9=1,SUMIF($A$3:$A$1622,A9,$L$3:$L$1622),0) -> 4 | AC9: =IF(I9="",0,L9*IFERROR(INDEX(کاتالوگ_محصولات!$G$4:$G$303,MATCH(I9,کاتالوگ_محصولات!$A$4:$A$303,0)),0)) -> 0 | AD9: =IF(A9="",0,O9-AC9) -> 1800000 | AE9: =IF(B9="","",LEFT(B9,7)) -> 1405/07
A10: INV-0205 | B10: 1405/07/03 | C10: 2 | D10: ماحی حمیدپور | E10: full | F10: اسنپ پی | G10: جدید | H10: کانال | J10: کت ژاکارد صورتی 1 | K10: کت ژاکارد صورتی 1 | L10: 1 | M10: 3850000 | N10: 0 | O10: 3850000 | P10: سمیرا | Q10: باجلان | R10: 9383159588 | S10: 2 | T10: 8 | V10: =IF(A10="",0,IF(COUNTIF($A$3:A10,A10)=1,1,0)) -> 0 | W10: =IF(A10="",0,L10*M10) -> 3850000 | X10: =IF(R10<>"",R10,IF(AND(P10<>"",Q10<>""),P10&"|"&Q10,"")) -> 9383159588 | Y10: =IF(X10="",0,IF(COUNTIF($X$3:X10,X10)=1,1,0)) -> 0 | Z10: =IF(V10<>1,0,IF(X10="",0,IF(COUNTIF($X$3:X9,X10)>0,1,0))) -> 0 | AA10: =IF(V10=1,SUMIF($A$3:$A$1622,A10,$O$3:$O$1622),0) -> 0 | AB10: =IF(V10=1,SUMIF($A$3:$A$1622,A10,$L$3:$L$1622),0) -> 0 | AC10: =IF(I10="",0,L10*IFERROR(INDEX(کاتالوگ_محصولات!$G$4:$G$303,MATCH(I10,کاتالوگ_محصولات!$A$4:$A$303,0)),0)) -> 0 | AD10: =IF(A10="",0,O10-AC10) -> 3850000 | AE10: =IF(B10="","",LEFT(B10,7)) -> 1405/07
A11: INV-0205 | B11: 1405/07/03 | C11: 2 | D11: ماحی حمیدپور | E11: full | F11: اسنپ پی | G11: جدید | H11: کانال | J11: کت ژاکارد ابی سایز 1 | K11: کت ژاکارد ابی سایز 1 | L11: 1 | M11: 3850000 | N11: 0 | O11: 3850000 | P11: سمیرا | Q11: باجلان | R11: 9383159588 | S11: 2 | T11: 8 | V11: =IF(A11="",0,IF(COUNTIF($A$3:A11,A11)=1,1,0)) -> 0 | W11: =IF(A11="",0,L11*M11) -> 3850000 | X11: =IF(R11<>"",R11,IF(AND(P11<>"",Q11<>""),P11&"|"&Q11,"")) -> 9383159588 | Y11: =IF(X11="",0,IF(COUNTIF($X$3:X11,X11)=1,1,0)) -> 0 | Z11: =IF(V11<>1,0,IF(X11="",0,IF(COUNTIF($X$3:X10,X11)>0,1,0))) -> 0 | AA11: =IF(V11=1,SUMIF($A$3:$A$1622,A11,$O$3:$O$1622),0) -> 0 | AB11: =IF(V11=1,SUMIF($A$3:$A$1622,A11,$L$3:$L$1622),0) -> 0 | AC11: =IF(I11="",0,L11*IFERROR(INDEX(کاتالوگ_محصولات!$G$4:$G$303,MATCH(I11,کاتالوگ_محصولات!$A$4:$A$303,0)),0)) -> 0 | AD11: =IF(A11="",0,O11-AC11) -> 3850000 | AE11: =IF(B11="","",LEFT(B11,7)) -> 1405/07
A12: INV-0205 | B12: 1405/07/03 | C12: 2 | D12: ماحی حمیدپور | E12: full | F12: اسنپ پی | G12: جدید | H12: کانال | J12: کت شنل سایز1 | K12: کت شنل سایز1 | L12: 1 | M12: 4250000 | N12: 0 | O12: 4250000 | P12: سمیرا | Q12: باجلان | R12: 9383159588 | S12: 2 | T12: 8 | V12: =IF(A12="",0,IF(COUNTIF($A$3:A12,A12)=1,1,0)) -> 0 | W12: =IF(A12="",0,L12*M12) -> 4250000 | X12: =IF(R12<>"",R12,IF(AND(P12<>"",Q12<>""),P12&"|"&Q12,"")) -> 9383159588 | Y12: =IF(X12="",0,IF(COUNTIF($X$3:X12,X12)=1,1,0)) -> 0 | Z12: =IF(V12<>1,0,IF(X12="",0,IF(COUNTIF($X$3:X11,X12)>0,1,0))) -> 0 | AA12: =IF(V12=1,SUMIF($A$3:$A$1622,A12,$O$3:$O$1622),0) -> 0 | AB12: =IF(V12=1,SUMIF($A$3:$A$1622,A12,$L$3:$L$1622),0) -> 0 | AC12: =IF(I12="",0,L12*IFERROR(INDEX(کاتالوگ_محصولات!$G$4:$G$303,MATCH(I12,کاتالوگ_محصولات!$A$4:$A$303,0)),0)) -> 0 | AD12: =IF(A12="",0,O12-AC12) -> 4250000 | AE12: =IF(B12="","",LEFT(B12,7)) -> 1405/07
A13: INV-0206 | B13: 1405/07/03 | C13: 2 | D13: ماحی حمیدپور | E13: full | F13: کارت | G13: جدید | H13: کانال | J13: کیف سرمه ای 4095 | K13: کیف سرمه ای 4095 | L13: 1 | M13: 2680000 | N13: 0 | O13: 2680000 | P13: نرگس | Q13: رامشک | R13: 9126998490 | S13: 29 | T13: 8 | V13: =IF(A13="",0,IF(COUNTIF($A$3:A13,A13)=1,1,0)) -> 1 | W13: =IF(A13="",0,L13*M13) -> 2680000 | X13: =IF(R13<>"",R13,IF(AND(P13<>"",Q13<>""),P13&"|"&Q13,"")) -> 9126998490 | Y13: =IF(X13="",0,IF(COUNTIF($X$3:X13,X13)=1,1,0)) -> 1 | Z13: =IF(V13<>1,0,IF(X13="",0,IF(COUNTIF($X$3:X12,X13)>0,1,0))) -> 0 | AA13: =IF(V13=1,SUMIF($A$3:$A$1622,A13,$O$3:$O$1622),0) -> 8440000 | AB13: =IF(V13=1,SUMIF($A$3:$A$1622,A13,$L$3:$L$1622),0) -> 3 | AC13: =IF(I13="",0,L13*IFERROR(INDEX(کاتالوگ_محصولات!$G$4:$G$303,MATCH(I13,کاتالوگ_محصولات!$A$4:$A$303,0)),0)) -> 0 | AD13: =IF(A13="",0,O13-AC13) -> 2680000 | AE13: =IF(B13="","",LEFT(B13,7)) -> 1405/07
A14: INV-0206 | B14: 1405/07/03 | C14: 2 | D14: ماحی حمیدپور | E14: full | F14: کارت | G14: جدید | H14: کانال | J14: شومیز دریا صورتی سایز1 | K14: شومیز دریا صورتی سایز1 | L14: 1 | M14: 1980000 | N14: 0 | O14: 1980000 | P14: نرگس | Q14: رامشک | R14: 9126998490 | S14: 29 | T14: 8 | V14: =IF(A14="",0,IF(COUNTIF($A$3:A14,A14)=1,1,0)) -> 0 | W14: =IF(A14="",0,L14*M14) -> 1980000 | X14: =IF(R14<>"",R14,IF(AND(P14<>"",Q14<>""),P14&"|"&Q14,"")) -> 9126998490 | Y14: =IF(X14="",0,IF(COUNTIF($X$3:X14,X14)=1,1,0)) -> 0 | Z14: =IF(V14<>1,0,IF(X14="",0,IF(COUNTIF($X$3:X13,X14)>0,1,0))) -> 0 | AA14: =IF(V14=1,SUMIF($A$3:$A$1622,A14,$O$3:$O$1622),0) -> 0 | AB14: =IF(V14=1,SUMIF($A$3:$A$1622,A14,$L$3:$L$1622),0) -> 0 | AC14: =IF(I14="",0,L14*IFERROR(INDEX(کاتالوگ_محصولات!$G$4:$G$303,MATCH(I14,کاتالوگ_محصولات!$A$4:$A$303,0)),0)) -> 0 | AD14: =IF(A14="",0,O14-AC14) -> 1980000 | AE14: =IF(B14="","",LEFT(B14,7)) -> 1405/07
A15: INV-0206 | B15: 1405/07/03 | C15: 2 | D15: ماحی حمیدپور | E15: full | F15: کارت | G15: جدید | H15: کانال | J15: شلوار بوتکات سرمه ای40 | K15: شلوار بوتکات سرمه ای40 | L15: 1 | M15: 3780000 | N15: 0 | O15: 3780000 | P15: نرگس | Q15: رامشک | R15: 9126998490 | S15: 29 | T15: 8 | V15: =IF(A15="",0,IF(COUNTIF($A$3:A15,A15)=1,1,0)) -> 0 | W15: =IF(A15="",0,L15*M15) -> 3780000 | X15: =IF(R15<>"",R15,IF(AND(P15<>"",Q15<>""),P15&"|"&Q15,"")) -> 9126998490 | Y15: =IF(X15="",0,IF(COUNTIF($X$3:X15,X15)=1,1,0)) -> 0 | Z15: =IF(V15<>1,0,IF(X15="",0,IF(COUNTIF($X$3:X14,X15)>0,1,0))) -> 0 | AA15: =IF(V15=1,SUMIF($A$3:$A$1622,A15,$O$3:$O$1622),0) -> 0 | AB15: =IF(V15=1,SUMIF($A$3:$A$1622,A15,$L$3:$L$1622),0) -> 0 | AC15: =IF(I15="",0,L15*IFERROR(INDEX(کاتالوگ_محصولات!$G$4:$G$303,MATCH(I15,کاتالوگ_محصولات!$A$4:$A$303,0)),0)) -> 0 | AD15: =IF(A15="",0,O15-AC15) -> 3780000 | AE15: =IF(B15="","",LEFT(B15,7)) -> 1405/07
A16: INV-0207 | B16: 1405/07/03 | C16: 2 | D16: ماحی حمیدپور | E16: full | F16: کارت | G16: جدید | H16: کانال | J16: کت سبز | K16: کت سبز | L16: 1 | M16: 1800000 | N16: 0 | O16: 1800000 | Q16: باقری | R16: 9123637907 | S16: 1 | T16: 1344/01 | V16: =IF(A16="",0,IF(COUNTIF($A$3:A16,A16)=1,1,0)) -> 1 | W16: =IF(A16="",0,L16*M16) -> 1800000 | X16: =IF(R16<>"",R16,IF(AND(P16<>"",Q16<>""),P16&"|"&Q16,"")) -> 9123637907 | Y16: =IF(X16="",0,IF(COUNTIF($X$3:X16,X16)=1,1,0)) -> 1 | Z16: =IF(V16<>1,0,IF(X16="",0,IF(COUNTIF($X$3:X15,X16)>0,1,0))) -> 0 | AA16: =IF(V16=1,SUMIF($A$3:$A$1622,A16,$O$3:$O$1622),0) -> 8860000 | AB16: =IF(V16=1,SUMIF($A$3:$A$1622,A16,$L$3:$L$1622),0) -> 3 | AC16: =IF(I16="",0,L16*IFERROR(INDEX(کاتالوگ_محصولات!$G$4:$G$303,MATCH(I16,کاتالوگ_محصولات!$A$4:$A$303,0)),0)) -> 0 | AD16: =IF(A16="",0,O16-AC16) -> 1800000 | AE16: =IF(B16="","",LEFT(B16,7)) -> 1405/07
A17: INV-0207 | B17: 1405/07/03 | C17: 2 | D17: ماحی حمیدپور | E17: full | F17: کارت | G17: جدید | H17: کانال | J17: شلوار بوتکات سرمه ای48 | K17: شلوار بوتکات سرمه ای48 | L17: 1 | M17: 3780000 | N17: 0 | O17: 3780000 | Q17: باقری | R17: 9123637907 | S17: 1 | T17: 1344/01 | V17: =IF(A17="",0,IF(COUNTIF($A$3:A17,A17)=1,1,0)) -> 0 | W17: =IF(A17="",0,L17*M17) -> 3780000 | X17: =IF(R17<>"",R17,IF(AND(P17<>"",Q17<>""),P17&"|"&Q17,"")) -> 9123637907 | Y17: =IF(X17="",0,IF(COUNTIF($X$3:X17,X17)=1,1,0)) -> 0 | Z17: =IF(V17<>1,0,IF(X17="",0,IF(COUNTIF($X$3:X16,X17)>0,1,0))) -> 0 | AA17: =IF(V17=1,SUMIF($A$3:$A$1622,A17,$O$3:$O$1622),0) -> 0 | AB17: =IF(V17=1,SUMIF($A$3:$A$1622,A17,$L$3:$L$1622),0) -> 0 | AC17: =IF(I17="",0,L17*IFERROR(INDEX(کاتالوگ_محصولات!$G$4:$G$303,MATCH(I17,کاتالوگ_محصولات!$A$4:$A$303,0)),0)) -> 0 | AD17: =IF(A17="",0,O17-AC17) -> 3780000 | AE17: =IF(B17="","",LEFT(B17,7)) -> 1405/07
A18: INV-0207 | B18: 1405/07/03 | C18: 2 | D18: ماحی حمیدپور | E18: full | F18: کارت | G18: جدید | H18: کانال | J18: شومیز ساتن چری سرمه ای2 | K18: شومیز ساتن چری سرمه ای2 | L18: 1 | M18: 3280000 | N18: 0 | O18: 3280000 | Q18: باقری | R18: 9123637907 | S18: 1 | T18: 1344/01 | V18: =IF(A18="",0,IF(COUNTIF($A$3:A18,A18)=1,1,0)) -> 0 | W18: =IF(A18="",0,L18*M18) -> 3280000 | X18: =IF(R18<>"",R18,IF(AND(P18<>"",Q18<>""),P18&"|"&Q18,"")) -> 9123637907 | Y18: =IF(X18="",0,IF(COUNTIF($X$3:X18,X18)=1,1,0)) -> 0 | Z18: =IF(V18<>1,0,IF(X18="",0,IF(COUNTIF($X$3:X17,X18)>0,1,0))) -> 0 | AA18: =IF(V18=1,SUMIF($A$3:$A$1622,A18,$O$3:$O$1622),0) -> 0 | AB18: =IF(V18=1,SUMIF($A$3:$A$1622,A18,$L$3:$L$1622),0) -> 0 | AC18: =IF(I18="",0,L18*IFERROR(INDEX(کاتالوگ_محصولات!$G$4:$G$303,MATCH(I18,کاتالوگ_محصولات!$A$4:$A$303,0)),0)) -> 0 | AD18: =IF(A18="",0,O18-AC18) -> 3280000 | AE18: =IF(B18="","",LEFT(B18,7)) -> 1405/07
A19: INV-0208 | B19: 1405/07/03 | C19: 2 | D19: ماحی حمیدپور | E19: full | F19: اسنپ پی | G19: جدید | H19: کانال | J19: کت ژاکارد طوسی | K19: کت ژاکارد طوسی | L19: 1 | M19: 3290000 | N19: 0 | O19: 3290000 | P19: مهران | R19: 9121242431 | S19: 7 | T19: 1 | V19: =IF(A19="",0,IF(COUNTIF($A$3:A19,A19)=1,1,0)) -> 1 | W19: =IF(A19="",0,L19*M19) -> 3290000 | X19: =IF(R19<>"",R19,IF(AND(P19<>"",Q19<>""),P19&"|"&Q19,"")) -> 9121242431 | Y19: =IF(X19="",0,IF(COUNTIF($X$3:X19,X19)=1,1,0)) -> 1 | Z19: =IF(V19<>1,0,IF(X19="",0,IF(COUNTIF($X$3:X18,X19)>0,1,0))) -> 0 | AA19: =IF(V19=1,SUMIF($A$3:$A$1622,A19,$O$3:$O$1622),0) -> 7670000 | AB19: =IF(V19=1,SUMIF($A$3:$A$1622,A19,$L$3:$L$1622),0) -> 3 | AC19: =IF(I19="",0,L19*IFERROR(INDEX(کاتالوگ_محصولات!$G$4:$G$303,MATCH(I19,کاتالوگ_محصولات!$A$4:$A$303,0)),0)) -> 0 | AD19: =IF(A19="",0,O19-AC19) -> 3290000 | AE19: =IF(B19="","",LEFT(B19,7)) -> 1405/07
A20: INV-0208 | B20: 1405/07/03 | C20: 2 | D20: ماحی حمیدپور | E20: full | F20: اسنپ پی | G20: جدید | H20: کانال | J20: وست بیژو آبی نفتی فری | K20: وست بیژو آبی نفتی فری | L20: 1 | M20: 3200000 | N20: 0 | O20: 3200000 | P20: مهران | R20: 9121242431 | S20: 7 | T20: 1 | V20: =IF(A20="",0,IF(COUNTIF($A$3:A20,A20)=1,1,0)) -> 0 | W20: =IF(A20="",0,L20*M20) -> 3200000 | X20: =IF(R20<>"",R20,IF(AND(P20<>"",Q20<>""),P20&"|"&Q20,"")) -> 9121242431 | Y20: =IF(X20="",0,IF(COUNTIF($X$3:X20,X20)=1,1,0)) -> 0 | Z20: =IF(V20<>1,0,IF(X20="",0,IF(COUNTIF($X$3:X19,X20)>0,1,0))) -> 0 | AA20: =IF(V20=1,SUMIF($A$3:$A$1622,A20,$O$3:$O$1622),0) -> 0 | AB20: =IF(V20=1,SUMIF($A$3:$A$1622,A20,$L$3:$L$1622),0) -> 0 | AC20: =IF(I20="",0,L20*IFERROR(INDEX(کاتالوگ_محصولات!$G$4:$G$303,MATCH(I20,کاتالوگ_محصولات!$A$4:$A$303,0)),0)) -> 0 | AD20: =IF(A20="",0,O20-AC20) -> 3200000 | AE20: =IF(B20="","",LEFT(B20,7)) -> 1405/07
A21: INV-0208 | B21: 1405/07/03 | C21: 2 | D21: ماحی حمیدپور | E21: full | F21: اسنپ پی | G21: جدید | H21: کانال | J21: شلوار بیژو آبی نفتی فری | K21: شلوار بیژو آبی نفتی فری | L21: 1 | M21: 1180000 | N21: 0 | O21: 1180000 | P21: مهران | R21: 9121242431 | S21: 7 | T21: 1 | V21: =IF(A21="",0,IF(COUNTIF($A$3:A21,A21)=1,1,0)) -> 0 | W21: =IF(A21="",0,L21*M21) -> 1180000 | X21: =IF(R21<>"",R21,IF(AND(P21<>"",Q21<>""),P21&"|"&Q21,"")) -> 9121242431 | Y21: =IF(X21="",0,IF(COUNTIF($X$3:X21,X21)=1,1,0)) -> 0 | Z21: =IF(V21<>1,0,IF(X21="",0,IF(COUNTIF($X$3:X20,X21)>0,1,0))) -> 0 | AA21: =IF(V21=1,SUMIF($A$3:$A$1622,A21,$O$3:$O$1622),0) -> 0 | AB21: =IF(V21=1,SUMIF($A$3:$A$1622,A21,$L$3:$L$1622),0) -> 0 | AC21: =IF(I21="",0,L21*IFERROR(INDEX(کاتالوگ_محصولات!$G$4:$G$303,MATCH(I21,کاتالوگ_محصولات!$A$4:$A$303,0)),0)) -> 0 | AD21: =IF(A21="",0,O21-AC21) -> 1180000 | AE21: =IF(B21="","",LEFT(B21,7)) -> 1405/07
A22: INV-0209 | B22: 1405/07/03 | C22: 2 | D22: ماحی حمیدپور | E22: full | F22: اسنپ پی | G22: جدید | H22: کانال | J22: بامبر ژکت سبز | K22: بامبر ژکت سبز | L22: 1 | M22: 6780000 | N22: 0 | O22: 6780000 | P22: مهسا | Q22: سعدی | R22: 9918681529 | V22: =IF(A22="",0,IF(COUNTIF($A$3:A22,A22)=1,1,0)) -> 1 | W22: =IF(A22="",0,L22*M22) -> 6780000 | X22: =IF(R22<>"",R22,IF(AND(P22<>"",Q22<>""),P22&"|"&Q22,"")) -> 9918681529 | Y22: =IF(X22="",0,IF(COUNTIF($X$3:X22,X22)=1,1,0)) -> 1 | Z22: =IF(V22<>1,0,IF(X22="",0,IF(COUNTIF($X$3:X21,X22)>0,1,0))) -> 0 | AA22: =IF(V22=1,SUMIF($A$3:$A$1622,A22,$O$3:$O$1622),0) -> 6780000 | AB22: =IF(V22=1,SUMIF($A$3:$A$1622,A22,$L$3:$L$1622),0) -> 1 | AC22: =IF(I22="",0,L22*IFERROR(INDEX(کاتالوگ_محصولات!$G$4:$G$303,MATCH(I22,کاتالوگ_محصولات!$A$4:$A$303,0)),0)) -> 0 | AD22: =IF(A22="",0,O22-AC22) -> 6780000 | AE22: =IF(B22="","",LEFT(B22,7)) -> 1405/07
A23: INV-0210 | B23: 1405/07/03 | C23: 2 | D23: ماحی حمیدپور | E23: full | F23: دیجی پی -کارت | G23: برگشتی | H23: کانال | J23: شلوار ساتن سبز2 | K23: شلوار ساتن سبز2 | L23: 1 | M23: 1540000 | N23: 0 | O23: 1540000 | P23: پریسا | Q23: حبیبی | R23: 9365161629 | S23: 11 | T23: 1378/07 | U23: دیجی پی3/900/000 | V23: =IF(A23="",0,IF(COUNTIF($A$3:A23,A23)=1,1,0)) -> 1 | W23: =IF(A23="",0,L23*M23) -> 1540000 | X23: =IF(R23<>"",R23,IF(AND(P23<>"",Q23<>""),P23&"|"&Q23,"")) -> 9365161629 | Y23: =IF(X23="",0,IF(COUNTIF($X$3:X23,X23)=1,1,0)) -> 1 | Z23: =IF(V23<>1,0,IF(X23="",0,IF(COUNTIF($X$3:X22,X23)>0,1,0))) -> 0 | AA23: =IF(V23=1,SUMIF($A$3:$A$1622,A23,$O$3:$O$1622),0) -> 6280000 | AB23: =IF(V23=1,SUMIF($A$3:$A$1622,A23,$L$3:$L$1622),0) -> 3 | AC23: =IF(I23="",0,L23*IFERROR(INDEX(کاتالوگ_محصولات!$G$4:$G$303,MATCH(I23,کاتالوگ_محصولات!$A$4:$A$303,0)),0)) -> 0 | AD23: =IF(A23="",0,O23-AC23) -> 1540000 | AE23: =IF(B23="","",LEFT(B23,7)) -> 1405/07
A24: INV-0210 | B24: 1405/07/03 | C24: 2 | D24: ماحی حمیدپور | E24: full | F24: دیجی پی -کارت | G24: برگشتی | H24: کانال | J24: شلوار ساتن سفید2 | K24: شلوار ساتن سفید2 | L24: 1 | M24: 1540000 | N24: 0 | O24: 1540000 | P24: پریسا | Q24: حبیبی | R24: 9365161629 | S24: 11 | T24: 1378/07 | V24: =IF(A24="",0,IF(COUNTIF($A$3:A24,A24)=1,1,0)) -> 0 | W24: =IF(A24="",0,L24*M24) -> 1540000 | X24: =IF(R24<>"",R24,IF(AND(P24<>"",Q24<>""),P24&"|"&Q24,"")) -> 9365161629 | Y24: =IF(X24="",0,IF(COUNTIF($X$3:X24,X24)=1,1,0)) -> 0 | Z24: =IF(V24<>1,0,IF(X24="",0,IF(COUNTIF($X$3:X23,X24)>0,1,0))) -> 0 | AA24: =IF(V24=1,SUMIF($A$3:$A$1622,A24,$O$3:$O$1622),0) -> 0 | AB24: =IF(V24=1,SUMIF($A$3:$A$1622,A24,$L$3:$L$1622),0) -> 0 | AC24: =IF(I24="",0,L24*IFERROR(INDEX(کاتالوگ_محصولات!$G$4:$G$303,MATCH(I24,کاتالوگ_محصولات!$A$4:$A$303,0)),0)) -> 0 | AD24: =IF(A24="",0,O24-AC24) -> 1540000 | AE24: =IF(B24="","",LEFT(B24,7)) -> 1405/07
A25: INV-0210 | B25: 1405/07/03 | C25: 2 | D25: ماحی حمیدپور | E25: full | F25: دیجی پی -کارت | G25: برگشتی | H25: کانال | J25: شومیز مانلی سبز زیتونی 2 | K25: شومیز مانلی سبز زیتونی 2 | L25: 1 | M25: 3200000 | N25: 0 | O25: 3200000 | P25: پریسا | Q25: حبیبی | R25: 9365161629 | S25: 11 | T25: 1378/07 | V25: =IF(A25="",0,IF(COUNTIF($A$3:A25,A25)=1,1,0)) -> 0 | W25: =IF(A25="",0,L25*M25) -> 3200000 | X25: =IF(R25<>"",R25,IF(AND(P25<>"",Q25<>""),P25&"|"&Q25,"")) -> 9365161629 | Y25: =IF(X25="",0,IF(COUNTIF($X$3:X25,X25)=1,1,0)) -> 0 | Z25: =IF(V25<>1,0,IF(X25="",0,IF(COUNTIF($X$3:X24,X25)>0,1,0))) -> 0 | AA25: =IF(V25=1,SUMIF($A$3:$A$1622,A25,$O$3:$O$1622),0) -> 0 | AB25: =IF(V25=1,SUMIF($A$3:$A$1622,A25,$L$3:$L$1622),0) -> 0 | AC25: =IF(I25="",0,L25*IFERROR(INDEX(کاتالوگ_محصولات!$G$4:$G$303,MATCH(I25,کاتالوگ_محصولات!$A$4:$A$303,0)),0)) -> 0 | AD25: =IF(A25="",0,O25-AC25) -> 3200000 | AE25: =IF(B25="","",LEFT(B25,7)) -> 1405/07
A26: INV-0211 | B26: 1405/07/03 | C26: 2 | D26: ماحی حمیدپور | E26: full | F26: کارت | G26: جدید | H26: کانال | J26: بامبر ژکت سبز | K26: بامبر ژکت سبز | L26: 1 | M26: 6780000 | N26: 0 | O26: 6780000 | P26: امیر | Q26: شماعی | R26: 909630096 | V26: =IF(A26="",0,IF(COUNTIF($A$3:A26,A26)=1,1,0)) -> 1 | W26: =IF(A26="",0,L26*M26) -> 6780000 | X26: =IF(R26<>"",R26,IF(AND(P26<>"",Q26<>""),P26&"|"&Q26,"")) -> 909630096 | Y26: =IF(X26="",0,IF(COUNTIF($X$3:X26,X26)=1,1,0)) -> 1 | Z26: =IF(V26<>1,0,IF(X26="",0,IF(COUNTIF($X$3:X25,X26)>0,1,0))) -> 0 | AA26: =IF(V26=1,SUMIF($A$3:$A$1622,A26,$O$3:$O$1622),0) -> 6780000 | AB26: =IF(V26=1,SUMIF($A$3:$A$1622,A26,$L$3:$L$1622),0) -> 1 | AC26: =IF(I26="",0,L26*IFERROR(INDEX(کاتالوگ_محصولات!$G$4:$G$303,MATCH(I26,کاتالوگ_محصولات!$A$4:$A$303,0)),0)) -> 0 | AD26: =IF(A26="",0,O26-AC26) -> 6780000 | AE26: =IF(B26="","",LEFT(B26,7)) -> 1405/07
A27: INV-0212 | B27: 1405/07/03 | C27: 1 | D27: دریا کریمی | E27: PM | F27: اسنپ پی | G27: چدید | H27: کانال | J27: وست کرمی سایز 1 | K27: وست کرمی سایز 1 | L27: 1 | M27: 1800000 | N27: 0 | O27: 1800000 | P27: ستایش | Q27: رضازاده | R27: 9120292707 | S27: 22 | T27: 1380/06 | U27: آپ سل 15 میلیونی | V27: =IF(A27="",0,IF(COUNTIF($A$3:A27,A27)=1,1,0)) -> 1 | W27: =IF(A27="",0,L27*M27) -> 1800000 | X27: =IF(R27<>"",R27,IF(AND(P27<>"",Q27<>""),P27&"|"&Q27,"")) -> 9120292707 | Y27: =IF(X27="",0,IF(COUNTIF($X$3:X27,X27)=1,1,0)) -> 1 | Z27: =IF(V27<>1,0,IF(X27="",0,IF(COUNTIF($X$3:X26,X27)>0,1,0))) -> 0 | AA27: =IF(V27=1,SUMIF($A$3:$A$1622,A27,$O$3:$O$1622),0) -> 15190000 | AB27: =IF(V27=1,SUMIF($A$3:$A$1622,A27,$L$3:$L$1622),0) -> 6 | AC27: =IF(I27="",0,L27*IFERROR(INDEX(کاتالوگ_محصولات!$G$4:$G$303,MATCH(I27,کاتالوگ_محصولات!$A$4:$A$303,0)),0)) -> 0 | AD27: =IF(A27="",0,O27-AC27) -> 1800000 | AE27: =IF(B27="","",LEFT(B27,7)) -> 1405/07
A28: INV-0212 | B28: 1405/07/03 | C28: 1 | D28: دریا کریمی | E28: PM | F28: اسنپ پی | G28: چدید | H28: کانال | J28: دامن لیدی مشکی فری | K28: دامن لیدی مشکی فری | L28: 1 | M28: 2950000 | N28: 0 | O28: 2950000 | P28: ستایش | Q28: رضازاده | R28: 9120292707 | S28: 22 | T28: 1380/06 | V28: =IF(A28="",0,IF(COUNTIF($A$3:A28,A28)=1,1,0)) -> 0 | W28: =IF(A28="",0,L28*M28) -> 2950000 | X28: =IF(R28<>"",R28,IF(AND(P28<>"",Q28<>""),P28&"|"&Q28,"")) -> 9120292707 | Y28: =IF(X28="",0,IF(COUNTIF($X$3:X28,X28)=1,1,0)) -> 0 | Z28: =IF(V28<>1,0,IF(X28="",0,IF(COUNTIF($X$3:X27,X28)>0,1,0))) -> 0 | AA28: =IF(V28=1,SUMIF($A$3:$A$1622,A28,$O$3:$O$1622),0) -> 0 | AB28: =IF(V28=1,SUMIF($A$3:$A$1622,A28,$L$3:$L$1622),0) -> 0 | AC28: =IF(I28="",0,L28*IFERROR(INDEX(کاتالوگ_محصولات!$G$4:$G$303,MATCH(I28,کاتالوگ_محصولات!$A$4:$A$303,0)),0)) -> 0 | AD28: =IF(A28="",0,O28-AC28) -> 2950000 | AE28: =IF(B28="","",LEFT(B28,7)) -> 1405/07
A29: INV-0212 | B29: 1405/07/03 | C29: 1 | D29: دریا کریمی | E29: PM | F29: اسنپ پی | G29: چدید | H29: کانال | J29: شومیز مانلی کرم2 | K29: شومیز مانلی کرم2 | L29: 1 | M29: 3200000 | N29: 0 | O29: 3200000 | P29: ستایش | Q29: رضازاده | R29: 9120292707 | S29: 22 | T29: 1380/06 | V29: =IF(A29="",0,IF(COUNTIF($A$3:A29,A29)=1,1,0)) -> 0 | W29: =IF(A29="",0,L29*M29) -> 3200000 | X29: =IF(R29<>"",R29,IF(AND(P29<>"",Q29<>""),P29&"|"&Q29,"")) -> 9120292707 | Y29: =IF(X29="",0,IF(COUNTIF($X$3:X29,X29)=1,1,0)) -> 0 | Z29: =IF(V29<>1,0,IF(X29="",0,IF(COUNTIF($X$3:X28,X29)>0,1,0))) -> 0 | AA29: =IF(V29=1,SUMIF($A$3:$A$1622,A29,$O$3:$O$1622),0) -> 0 | AB29: =IF(V29=1,SUMIF($A$3:$A$1622,A29,$L$3:$L$1622),0) -> 0 | AC29: =IF(I29="",0,L29*IFERROR(INDEX(کاتالوگ_محصولات!$G$4:$G$303,MATCH(I29,کاتالوگ_محصولات!$A$4:$A$303,0)),0)) -> 0 | AD29: =IF(A29="",0,O29-AC29) -> 3200000 | AE29: =IF(B29="","",LEFT(B29,7)) -> 1405/07
A30: INV-0212 | B30: 1405/07/03 | C30: 1 | D30: دریا کریمی | E30: PM | F30: اسنپ پی | G30: چدید | H30: کانال | J30: بافت یقه ایستاده کرم | K30: بافت یقه ایستاده کرم | L30: 1 | M30: 2180000 | N30: 0 | O30: 2180000 | P30: ستایش | Q30: رضازاده | R30: 9120292707 | S30: 22 | T30: 1380/06 | V30: =IF(A30="",0,IF(COUNTIF($A$3:A30,A30)=1,1,0)) -> 0 | W30: =IF(A30="",0,L30*M30) -> 2180000 | X30: =IF(R30<>"",R30,IF(AND(P30<>"",Q30<>""),P30&"|"&Q30,"")) -> 9120292707 | Y30: =IF(X30="",0,IF(COUNTIF($X$3:X30,X30)=1,1,0)) -> 0 | Z30: =IF(V30<>1,0,IF(X30="",0,IF(COUNTIF($X$3:X29,X30)>0,1,0))) -> 0 | AA30: =IF(V30=1,SUMIF($A$3:$A$1622,A30,$O$3:$O$1622),0) -> 0 | AB30: =IF(V30=1,SUMIF($A$3:$A$1622,A30,$L$3:$L$1622),0) -> 0 | AC30: =IF(I30="",0,L30*IFERROR(INDEX(کاتالوگ_محصولات!$G$4:$G$303,MATCH(I30,کاتالوگ_محصولات!$A$4:$A$303,0)),0)) -> 0 | AD30: =IF(A30="",0,O30-AC30) -> 2180000 | AE30: =IF(B30="","",LEFT(B30,7)) -> 1405/07
A31: INV-0212 | B31: 1405/07/03 | C31: 1 | D31: دریا کریمی | E31: PM | F31: اسنپ پی | G31: چدید | H31: کانال | J31: بافت یقه ایستاده مشکی | K31: بافت یقه ایستاده مشکی | L31: 1 | M31: 2180000 | N31: 0 | O31: 2180000 | P31: ستایش | Q31: رضازاده | R31: 9120292707 | S31: 22 | T31: 1380/06 | V31: =IF(A31="",0,IF(COUNTIF($A$3:A31,A31)=1,1,0)) -> 0 | W31: =IF(A31="",0,L31*M31) -> 2180000 | X31: =IF(R31<>"",R31,IF(AND(P31<>"",Q31<>""),P31&"|"&Q31,"")) -> 9120292707 | Y31: =IF(X31="",0,IF(COUNTIF($X$3:X31,X31)=1,1,0)) -> 0 | Z31: =IF(V31<>1,0,IF(X31="",0,IF(COUNTIF($X$3:X30,X31)>0,1,0))) -> 0 | AA31: =IF(V31=1,SUMIF($A$3:$A$1622,A31,$O$3:$O$1622),0) -> 0 | AB31: =IF(V31=1,SUMIF($A$3:$A$1622,A31,$L$3:$L$1622),0) -> 0 | AC31: =IF(I31="",0,L31*IFERROR(INDEX(کاتالوگ_محصولات!$G$4:$G$303,MATCH(I31,کاتالوگ_محصولات!$A$4:$A$303,0)),0)) -> 0 | AD31: =IF(A31="",0,O31-AC31) -> 2180000 | AE31: =IF(B31="","",LEFT(B31,7)) -> 1405/07
A32: INV-0212 | B32: 1405/07/03 | C32: 1 | D32: دریا کریمی | E32: PM | F32: اسنپ پی | G32: چدید | H32: کانال | J32: کیف کرم قهوه ای 4194 | K32: کیف کرم قهوه ای 4194 | L32: 1 | M32: 2880000 | N32: 0 | O32: 2880000 | P32: ستایش | Q32: رضازاده | R32: 9120292707 | S32: 22 | T32: 1380/06 | V32: =IF(A32="",0,IF(COUNTIF($A$3:A32,A32)=1,1,0)) -> 0 | W32: =IF(A32="",0,L32*M32) -> 2880000 | X32: =IF(R32<>"",R32,IF(AND(P32<>"",Q32<>""),P32&"|"&Q32,"")) -> 9120292707 | Y32: =IF(X32="",0,IF(COUNTIF($X$3:X32,X32)=1,1,0)) -> 0 | Z32: =IF(V32<>1,0,IF(X32="",0,IF(COUNTIF($X$3:X31,X32)>0,1,0))) -> 0 | AA32: =IF(V32=1,SUMIF($A$3:$A$1622,A32,$O$3:$O$1622),0) -> 0 | AB32: =IF(V32=1,SUMIF($A$3:$A$1622,A32,$L$3:$L$1622),0) -> 0 | AC32: =IF(I32="",0,L32*IFERROR(INDEX(کاتالوگ_محصولات!$G$4:$G$303,MATCH(I32,کاتالوگ_محصولات!$A$4:$A$303,0)),0)) -> 0 | AD32: =IF(A32="",0,O32-AC32) -> 2880000 | AE32: =IF(B32="","",LEFT(B32,7)) -> 1405/07
A33: INV-0213 | B33: 1405/07/03 | C33: 1 | D33: دریا کریمی | E33: PM | F33: کارت | G33: جدید | H33: کانال | J33: تاپ بند ماکارون | K33: تاپ بند ماکارون | L33: 1 | M33: 928000 | N33: 0 | O33: 928000 | Q33: اعتمادی | R33: 9026666570 | S33: 25 | T33: 1370/11 | V33: =IF(A33="",0,IF(COUNTIF($A$3:A33,A33)=1,1,0)) -> 1 | W33: =IF(A33="",0,L33*M33) -> 928000 | X33: =IF(R33<>"",R33,IF(AND(P33<>"",Q33<>""),P33&"|"&Q33,"")) -> 9026666570 | Y33: =IF(X33="",0,IF(COUNTIF($X$3:X33,X33)=1,1,0)) -> 1 | Z33: =IF(V33<>1,0,IF(X33="",0,IF(COUNTIF($X$3:X32,X33)>0,1,0))) -> 0 | AA33: =IF(V33=1,SUMIF($A$3:$A$1622,A33,$O$3:$O$1622),0) -> 928000 | AB33: =IF(V33=1,SUMIF($A$3:$A$1622,A33,$L$3:$L$1622),0) -> 1 | AC33: =IF(I33="",0,L33*IFERROR(INDEX(کاتالوگ_محصولات!$G$4:$G$303,MATCH(I33,کاتالوگ_محصولات!$A$4:$A$303,0)),0)) -> 0 | AD33: =IF(A33="",0,O33-AC33) -> 928000 | AE33: =IF(B33="","",LEFT(B33,7)) -> 1405/07
A34: INV-0214 | B34: 1405/07/04 | C34: 1 | D34: دریا کریمی | E34: pm | F34: کارت | G34: برگشتی | H34: کانال | J34: شومیز لینن سونای سرمه ای 1 | K34: شومیز لینن سونای سرمه ای 1 | L34: 1 | M34: 3380000 | N34: 0 | O34: 3380000 | P34: شیما | Q34: سعیدی | R34: 9124934558 | S34: 27 | T34: 1 | U34: مشتری برگشتی | V34: =IF(A34="",0,IF(COUNTIF($A$3:A34,A34)=1,1,0)) -> 1 | W34: =IF(A34="",0,L34*M34) -> 3380000 | X34: =IF(R34<>"",R34,IF(AND(P34<>"",Q34<>""),P34&"|"&Q34,"")) -> 9124934558 | Y34: =IF(X34="",0,IF(COUNTIF($X$3:X34,X34)=1,1,0)) -> 1 | Z34: =IF(V34<>1,0,IF(X34="",0,IF(COUNTIF($X$3:X33,X34)>0,1,0))) -> 0 | AA34: =IF(V34=1,SUMIF($A$3:$A$1622,A34,$O$3:$O$1622),0) -> 3380000 | AB34: =IF(V34=1,SUMIF($A$3:$A$1622,A34,$L$3:$L$1622),0) -> 1 | AC34: =IF(I34="",0,L34*IFERROR(INDEX(کاتالوگ_محصولات!$G$4:$G$303,MATCH(I34,کاتالوگ_محصولات!$A$4:$A$303,0)),0)) -> 0 | AD34: =IF(A34="",0,O34-AC34) -> 3380000 | AE34: =IF(B34="","",LEFT(B34,7)) -> 1405/07
A35: INV-0215 | B35: 1405/07/04 | C35: 1 | D35: دریا کریمی | E35: _PM_ | F35: کارت | G35: جدید | H35: کانال | J35: شلوار مانا کله غازی2 | K35: شلوار مانا کله غازی2 | L35: 1 | M35: 1680000 | N35: 0 | O35: 1680000 | P35: خانم | Q35: فرزان پور | R35: 9148931108 | S35: 28 | T35: 6 | V35: =IF(A35="",0,IF(COUNTIF($A$3:A35,A35)=1,1,0)) -> 1 | W35: =IF(A35="",0,L35*M35) -> 1680000 | X35: =IF(R35<>"",R35,IF(AND(P35<>"",Q35<>""),P35&"|"&Q35,"")) -> 9148931108 | Y35: =IF(X35="",0,IF(COUNTIF($X$3:X35,X35)=1,1,0)) -> 1 | Z35: =IF(V35<>1,0,IF(X35="",0,IF(COUNTIF($X$3:X34,X35)>0,1,0))) -> 0 | AA35: =IF(V35=1,SUMIF($A$3:$A$1622,A35,$O$3:$O$1622),0) -> 3000000 | AB35: =IF(V35=1,SUMIF($A$3:$A$1622,A35,$L$3:$L$1622),0) -> 2 | AC35: =IF(I35="",0,L35*IFERROR(INDEX(کاتالوگ_محصولات!$G$4:$G$303,MATCH(I35,کاتالوگ_محصولات!$A$4:$A$303,0)),0)) -> 0 | AD35: =IF(A35="",0,O35-AC35) -> 1680000 | AE35: =IF(B35="","",LEFT(B35,7)) -> 1405/07
A36: INV-0215 | B36: 1405/07/04 | C36: 1 | D36: دریا کریمی | E36: _PM_ | F36: کارت | G36: جدید | H36: کانال | J36: شومیز تایملس سبز فری | K36: شومیز تایملس سبز فری | L36: 1 | M36: 1320000 | N36: 0 | O36: 1320000 | P36: خانم | Q36: فرزان پور | R36: 9148931108 | S36: 28 | T36: 6 | V36: =IF(A36="",0,IF(COUNTIF($A$3:A36,A36)=1,1,0)) -> 0 | W36: =IF(A36="",0,L36*M36) -> 1320000 | X36: =IF(R36<>"",R36,IF(AND(P36<>"",Q36<>""),P36&"|"&Q36,"")) -> 9148931108 | Y36: =IF(X36="",0,IF(COUNTIF($X$3:X36,X36)=1,1,0)) -> 0 | Z36: =IF(V36<>1,0,IF(X36="",0,IF(COUNTIF($X$3:X35,X36)>0,1,0))) -> 0 | AA36: =IF(V36=1,SUMIF($A$3:$A$1622,A36,$O$3:$O$1622),0) -> 0 | AB36: =IF(V36=1,SUMIF($A$3:$A$1622,A36,$L$3:$L$1622),0) -> 0 | AC36: =IF(I36="",0,L36*IFERROR(INDEX(کاتالوگ_محصولات!$G$4:$G$303,MATCH(I36,کاتالوگ_محصولات!$A$4:$A$303,0)),0)) -> 0 | AD36: =IF(A36="",0,O36-AC36) -> 1320000 | AE36: =IF(B36="","",LEFT(B36,7)) -> 1405/07
A37: INV-0216 | B37: 1405/07/04 | C37: 1 | D37: دریا کریمی | E37: _PM_ | F37: کارت | H37: کانال | J37: شومیز حراجی گیپور ابی | K37: شومیز حراجی گیپور ابی | L37: 2 | M37: 1080000 | N37: 0 | O37: 2160000 | V37: =IF(A37="",0,IF(COUNTIF($A$3:A37,A37)=1,1,0)) -> 1 | W37: =IF(A37="",0,L37*M37) -> 2160000 | X37: =IF(R37<>"",R37,IF(AND(P37<>"",Q37<>""),P37&"|"&Q37,"")) | Y37: =IF(X37="",0,IF(COUNTIF($X$3:X37,X37)=1,1,0)) -> 0 | Z37: =IF(V37<>1,0,IF(X37="",0,IF(COUNTIF($X$3:X36,X37)>0,1,0))) -> 0 | AA37: =IF(V37=1,SUMIF($A$3:$A$1622,A37,$O$3:$O$1622),0) -> 2160000 | AB37: =IF(V37=1,SUMIF($A$3:$A$1622,A37,$L$3:$L$1622),0) -> 2 | AC37: =IF(I37="",0,L37*IFERROR(INDEX(کاتالوگ_محصولات!$G$4:$G$303,MATCH(I37,کاتالوگ_محصولات!$A$4:$A$303,0)),0)) -> 0 | AD37: =IF(A37="",0,O37-AC37) -> 2160000 | AE37: =IF(B37="","",LEFT(B37,7)) -> 1405/07
A38: INV-0217 | B38: 1405/07/04 | C38: 1 | D38: دریا کریمی | E38: _PM | F38: کارت | H38: کانال | J38: شومیز زبرا | K38: شومیز زبرا | L38: 1 | M38: 1680000 | N38: 0 | O38: 1680000 | P38: خانم | Q38: عنبری | R38: 9169513733 | S38: 2 | T38: 46031 | V38: =IF(A38="",0,IF(COUNTIF($A$3:A38,A38)=1,1,0)) -> 1 | W38: =IF(A38="",0,L38*M38) -> 1680000 | X38: =IF(R38<>"",R38,IF(AND(P38<>"",Q38<>""),P38&"|"&Q38,"")) -> 9169513733 | Y38: =IF(X38="",0,IF(COUNTIF($X$3:X38,X38)=1,1,0)) -> 1 | Z38: =IF(V38<>1,0,IF(X38="",0,IF(COUNTIF($X$3:X37,X38)>0,1,0))) -> 0 | AA38: =IF(V38=1,SUMIF($A$3:$A$1622,A38,$O$3:$O$1622),0) -> 1680000 | AB38: =IF(V38=1,SUMIF($A$3:$A$1622,A38,$L$3:$L$1622),0) -> 1 | AC38: =IF(I38="",0,L38*IFERROR(INDEX(کاتالوگ_محصولات!$G$4:$G$303,MATCH(I38,کاتالوگ_محصولات!$A$4:$A$303,0)),0)) -> 0 | AD38: =IF(A38="",0,O38-AC38) -> 1680000 | AE38: =IF(B38="","",LEFT(B38,7)) -> 1405/07
A39: INV-0218 | B39: 1405/07/04 | C39: 2 | D39: ماحی حمیدپور | F39: 5اسنپ1400پوز 2770کارت ب کارت | H39: کانال | J39: شومیز لیو سفید سایز1 | K39: شومیز لیو سفید سایز1 | L39: 1 | M39: 2630000 | N39: 0 | O39: 2630000 | P39: خانم | Q39: باقری | R39: 9932692491 | S39: 5 | T39: 8 | U39: ادامه فاکتور 161 | V39: =IF(A39="",0,IF(COUNTIF($A$3:A39,A39)=1,1,0)) -> 1 | W39: =IF(A39="",0,L39*M39) -> 2630000 | X39: =IF(R39<>"",R39,IF(AND(P39<>"",Q39<>""),P39&"|"&Q39,"")) -> 9932692491 | Y39: =IF(X39="",0,IF(COUNTIF($X$3:X39,X39)=1,1,0)) -> 1 | Z39: =IF(V39<>1,0,IF(X39="",0,IF(COUNTIF($X$3:X38,X39)>0,1,0))) -> 0 | AA39: =IF(V39=1,SUMIF($A$3:$A$1622,A39,$O$3:$O$1622),0) -> 4170000 | AB39: =IF(V39=1,SUMIF($A$3:$A$1622,A39,$L$3:$L$1622),0) -> 2 | AC39: =IF(I39="",0,L39*IFERROR(INDEX(کاتالوگ_محصولات!$G$4:$G$303,MATCH(I39,کاتالوگ_محصولات!$A$4:$A$303,0)),0)) -> 0 | AD39: =IF(A39="",0,O39-AC39) -> 2630000 | AE39: =IF(B39="","",LEFT(B39,7)) -> 1405/07
A40: INV-0218 | B40: 1405/07/04 | C40: 2 | D40: ماحی حمیدپور | F40: 5اسنپ1400پوز 2770کارت ب کارت | H40: کانال | J40: شلوار ساتن سبز2 | K40: شلوار ساتن سبز2 | L40: 1 | M40: 1540000 | N40: 0 | O40: 1540000 | P40: خانم | Q40: باقری | R40: 9932692491 | S40: 5 | T40: 8 | V40: =IF(A40="",0,IF(COUNTIF($A$3:A40,A40)=1,1,0)) -> 0 | W40: =IF(A40="",0,L40*M40) -> 1540000 | X40: =IF(R40<>"",R40,IF(AND(P40<>"",Q40<>""),P40&"|"&Q40,"")) -> 9932692491 | Y40: =IF(X40="",0,IF(COUNTIF($X$3:X40,X40)=1,1,0)) -> 0 | Z40: =IF(V40<>1,0,IF(X40="",0,IF(COUNTIF($X$3:X39,X40)>0,1,0))) -> 0 | AA40: =IF(V40=1,SUMIF($A$3:$A$1622,A40,$O$3:$O$1622),0) -> 0 | AB40: =IF(V40=1,SUMIF($A$3:$A$1622,A40,$L$3:$L$1622),0) -> 0 | AC40: =IF(I40="",0,L40*IFERROR(INDEX(کاتالوگ_محصولات!$G$4:$G$303,MATCH(I40,کاتالوگ_محصولات!$A$4:$A$303,0)),0)) -> 0 | AD40: =IF(A40="",0,O40-AC40) -> 1540000 | AE40: =IF(B40="","",LEFT(B40,7)) -> 1405/07
...

Sheet کاتالوگ_محصولات
A2: کاتالوگ محصولات
A3: SKU (خودکار) | B3: بارکد/شناسه Barcode | C3: نام محصول Product_Name | D3: دسته‌بندی Category | E3: پارچه Fabric | F3: فصل Season | G3: قیمت خرید Cost | H3: قیمت فروش Price | I3: موجودی اولیه Open_Stock | J3: فروخته شده Sold | K3: موجودی فعلی Curr_Stock | L3: وضعیت Status
A4: =IF(C4="","","SKU-"&TEXT(ROW()-3,"0000")) -> SKU-0001 | B4: CHSHLSNDCR2 | C4: شلوار لینن سندبادی کرم سایز1 | D4: شلوار | E4: Linen | F4: Spring/Summer | H4: 3490000 | I4: 9 | J4: =IFERROR(SUMIF(لاگ_فاکتور!$I$3:$I$1622,A4,لاگ_فاکتور!$L$3:$L$1622),0) -> 0 | K4: =MAX(0,I4-J4) -> 9 | L4: =IF(C4="","",IF(K4<=0,"🔴 تمام",IF(K4<=تنظیمات_سیستم!$C$7,"🟠 کم","🟢 OK"))) -> 🟢 OK
A5: =IF(C5="","","SKU-"&TEXT(ROW()-3,"0000")) -> SKU-0002 | B5: CHSHLSNDCR1 | C5: شلوار لینن سندبادی کرم سایز2 | D5: شلوار | E5: Linen | F5: Spring/Summer | H5: 3490000 | I5: 9 | J5: =IFERROR(SUMIF(لاگ_فاکتور!$I$3:$I$1622,A5,لاگ_فاکتور!$L$3:$L$1622),0) -> 0 | K5: =MAX(0,I5-J5) -> 9 | L5: =IF(C5="","",IF(K5<=0,"🔴 تمام",IF(K5<=تنظیمات_سیستم!$C$7,"🟠 کم","🟢 OK"))) -> 🟢 OK
A6: =IF(C6="","","SKU-"&TEXT(ROW()-3,"0000")) -> SKU-0003 | B6: CHSHLSNDBK1 | C6: شلوار لینن سندبادی مشکی سایز1 | D6: شلوار | E6: Linen | F6: Spring/Summer | H6: 3490000 | I6: 9 | J6: =IFERROR(SUMIF(لاگ_فاکتور!$I$3:$I$1622,A6,لاگ_فاکتور!$L$3:$L$1622),0) -> 0 | K6: =MAX(0,I6-J6) -> 9 | L6: =IF(C6="","",IF(K6<=0,"🔴 تمام",IF(K6<=تنظیمات_سیستم!$C$7,"🟠 کم","🟢 OK"))) -> 🟢 OK
A7: =IF(C7="","","SKU-"&TEXT(ROW()-3,"0000")) -> SKU-0004 | B7: CHSHLSNDBK2 | C7: شلوار لینن سندبادی مشکی سایز2 | D7: شلوار | E7: Linen | F7: Spring/Summer | H7: 3490000 | I7: 9 | J7: =IFERROR(SUMIF(لاگ_فاکتور!$I$3:$I$1622,A7,لاگ_فاکتور!$L$3:$L$1622),0) -> 0 | K7: =MAX(0,I7-J7) -> 9 | L7: =IF(C7="","",IF(K7<=0,"🔴 تمام",IF(K7<=تنظیمات_سیستم!$C$7,"🟠 کم","🟢 OK"))) -> 🟢 OK
A8: =IF(C8="","","SKU-"&TEXT(ROW()-3,"0000")) -> SKU-0005 | B8: CHSHLSNDBR1 | C8: شلوار لینن سندبادی قهوه ای سایز1 | D8: شلوار | E8: Linen | F8: Spring/Summer | H8: 3490000 | I8: 9 | J8: =IFERROR(SUMIF(لاگ_فاکتور!$I$3:$I$1622,A8,لاگ_فاکتور!$L$3:$L$1622),0) -> 0 | K8: =MAX(0,I8-J8) -> 9 | L8: =IF(C8="","",IF(K8<=0,"🔴 تمام",IF(K8<=تنظیمات_سیستم!$C$7,"🟠 کم","🟢 OK"))) -> 🟢 OK
A9: =IF(C9="","","SKU-"&TEXT(ROW()-3,"0000")) -> SKU-0006 | B9: CHSHLSNDBR2 | C9: شلوار لینن سندبادی قهوه ای سایز2 | D9: شلوار | E9: Linen | F9: Spring/Summer | H9: 3490000 | I9: 9 | J9: =IFERROR(SUMIF(لاگ_فاکتور!$I$3:$I$1622,A9,لاگ_فاکتور!$L$3:$L$1622),0) -> 0 | K9: =MAX(0,I9-J9) -> 9 | L9: =IF(C9="","",IF(K9<=0,"🔴 تمام",IF(K9<=تنظیمات_سیستم!$C$7,"🟠 کم","🟢 OK"))) -> 🟢 OK
A10: =IF(C10="","","SKU-"&TEXT(ROW()-3,"0000")) -> SKU-0007 | B10: CHSHLSNDMU1 | C10: شلوار لینن سندبادی سرمه ای سایز1 | D10: شلوار | E10: Linen | F10: Spring/Summer | H10: 3490000 | I10: 9 | J10: =IFERROR(SUMIF(لاگ_فاکتور!$I$3:$I$1622,A10,لاگ_فاکتور!$L$3:$L$1622),0) -> 0 | K10: =MAX(0,I10-J10) -> 9 | L10: =IF(C10="","",IF(K10<=0,"🔴 تمام",IF(K10<=تنظیمات_سیستم!$C$7,"🟠 کم","🟢 OK"))) -> 🟢 OK
A11: =IF(C11="","","SKU-"&TEXT(ROW()-3,"0000")) -> SKU-0008 | B11: CHSHLSNDMU2 | C11: شلوار لینن سندبادی سرمه ای سایز2 | D11: شلوار | E11: Linen | F11: Spring/Summer | H11: 3490000 | I11: 9 | J11: =IFERROR(SUMIF(لاگ_فاکتور!$I$3:$I$1622,A11,لاگ_فاکتور!$L$3:$L$1622),0) -> 0 | K11: =MAX(0,I11-J11) -> 9 | L11: =IF(C11="","",IF(K11<=0,"🔴 تمام",IF(K11<=تنظیمات_سیستم!$C$7,"🟠 کم","🟢 OK"))) -> 🟢 OK
A12: =IF(C12="","","SKU-"&TEXT(ROW()-3,"0000")) -> SKU-0009 | B12: CHSMSYHWH1 | C12: شومیز سایه سفید سایز1 | D12: شومیز | E12: Cotton | F12: All-Season | H12: 2480000 | I12: 9 | J12: =IFERROR(SUMIF(لاگ_فاکتور!$I$3:$I$1622,A12,لاگ_فاکتور!$L$3:$L$1622),0) -> 0 | K12: =MAX(0,I12-J12) -> 9 | L12: =IF(C12="","",IF(K12<=0,"🔴 تمام",IF(K12<=تنظیمات_سیستم!$C$7,"🟠 کم","🟢 OK"))) -> 🟢 OK
A13: =IF(C13="","","SKU-"&TEXT(ROW()-3,"0000")) -> SKU-0010 | C13: شومیز سایه سفید سایز2 | D13: شومیز | E13: Cotton | F13: All-Season | H13: 2480000 | I13: 9 | J13: =IFERROR(SUMIF(لاگ_فاکتور!$I$3:$I$1622,A13,لاگ_فاکتور!$L$3:$L$1622),0) -> 0 | K13: =MAX(0,I13-J13) -> 9 | L13: =IF(C13="","",IF(K13<=0,"🔴 تمام",IF(K13<=تنظیمات_سیستم!$C$7,"🟠 کم","🟢 OK"))) -> 🟢 OK
A14: =IF(C14="","","SKU-"&TEXT(ROW()-3,"0000")) -> SKU-0011 | B14: CHSMSYHBK1 | C14: شومیز سایه مشکی سایز1 | D14: شومیز | E14: Cotton | F14: All-Season | H14: 2480000 | I14: 9 | J14: =IFERROR(SUMIF(لاگ_فاکتور!$I$3:$I$1622,A14,لاگ_فاکتور!$L$3:$L$1622),0) -> 0 | K14: =MAX(0,I14-J14) -> 9 | L14: =IF(C14="","",IF(K14<=0,"🔴 تمام",IF(K14<=تنظیمات_سیستم!$C$7,"🟠 کم","🟢 OK"))) -> 🟢 OK
A15: =IF(C15="","","SKU-"&TEXT(ROW()-3,"0000")) -> SKU-0012 | B15: CHSMSYHBK2 | C15: شومیز سایه مشکی سایز2 | D15: شومیز | E15: Cotton | F15: All-Season | H15: 2480000 | I15: 9 | J15: =IFERROR(SUMIF(لاگ_فاکتور!$I$3:$I$1622,A15,لاگ_فاکتور!$L$3:$L$1622),0) -> 0 | K15: =MAX(0,I15-J15) -> 9 | L15: =IF(C15="","",IF(K15<=0,"🔴 تمام",IF(K15<=تنظیمات_سیستم!$C$7,"🟠 کم","🟢 OK"))) -> 🟢 OK
A16: =IF(C16="","","SKU-"&TEXT(ROW()-3,"0000")) -> SKU-0013 | B16: CHSMSYHWH2 | C16: شومیز سایه طوسی سایز1 | D16: شومیز | E16: Cotton | F16: All-Season | H16: 2480000 | I16: 9 | J16: =IFERROR(SUMIF(لاگ_فاکتور!$I$3:$I$1622,A16,لاگ_فاکتور!$L$3:$L$1622),0) -> 0 | K16: =MAX(0,I16-J16) -> 9 | L16: =IF(C16="","",IF(K16<=0,"🔴 تمام",IF(K16<=تنظیمات_سیستم!$C$7,"🟠 کم","🟢 OK"))) -> 🟢 OK
A17: =IF(C17="","","SKU-"&TEXT(ROW()-3,"0000")) -> SKU-0014 | B17: CHSMSYHBK2 | C17: شومیز سایه طوسی سایز2 | D17: شومیز | E17: Cotton | F17: All-Season | H17: 2480000 | I17: 9 | J17: =IFERROR(SUMIF(لاگ_فاکتور!$I$3:$I$1622,A17,لاگ_فاکتور!$L$3:$L$1622),0) -> 0 | K17: =MAX(0,I17-J17) -> 9 | L17: =IF(C17="","",IF(K17<=0,"🔴 تمام",IF(K17<=تنظیمات_سیستم!$C$7,"🟠 کم","🟢 OK"))) -> 🟢 OK
A18: =IF(C18="","","SKU-"&TEXT(ROW()-3,"0000")) -> SKU-0015 | B18: CHSMSYHGR1 | C18: شومیز سایه زرد سایز1 | D18: شومیز | E18: Cotton | F18: All-Season | H18: 2480000 | I18: 9 | J18: =IFERROR(SUMIF(لاگ_فاکتور!$I$3:$I$1622,A18,لاگ_فاکتور!$L$3:$L$1622),0) -> 0 | K18: =MAX(0,I18-J18) -> 9 | L18: =IF(C18="","",IF(K18<=0,"🔴 تمام",IF(K18<=تنظیمات_سیستم!$C$7,"🟠 کم","🟢 OK"))) -> 🟢 OK
A19: =IF(C19="","","SKU-"&TEXT(ROW()-3,"0000")) -> SKU-0016 | B19: CHSMSYHGR2 | C19: شومیز سایه زرد سایز2 | D19: شومیز | E19: Cotton | F19: All-Season | H19: 900000 | I19: 9 | J19: =IFERROR(SUMIF(لاگ_فاکتور!$I$3:$I$1622,A19,لاگ_فاکتور!$L$3:$L$1622),0) -> 0 | K19: =MAX(0,I19-J19) -> 9 | L19: =IF(C19="","",IF(K19<=0,"🔴 تمام",IF(K19<=تنظیمات_سیستم!$C$7,"🟠 کم","🟢 OK"))) -> 🟢 OK
A20: =IF(C20="","","SKU-"&TEXT(ROW()-3,"0000")) -> SKU-0017 | B20: CHSMSYHYL1 | C20: شومیز سایه خالدار سفیدزرد سایز1 | D20: شومیز | E20: Cotton | F20: All-Season | H20: 900000 | I20: 9 | J20: =IFERROR(SUMIF(لاگ_فاکتور!$I$3:$I$1622,A20,لاگ_فاکتور!$L$3:$L$1622),0) -> 0 | K20: =MAX(0,I20-J20) -> 9 | L20: =IF(C20="","",IF(K20<=0,"🔴 تمام",IF(K20<=تنظیمات_سیستم!$C$7,"🟠 کم","🟢 OK"))) -> 🟢 OK
A21: =IF(C21="","","SKU-"&TEXT(ROW()-3,"0000")) -> SKU-0018 | B21: CHSMSYHYL2 | C21: شومیز سایه خالدار سفیدزرد سایز2 | D21: شومیز | E21: Cotton | F21: All-Season | H21: 900000 | I21: 9 | J21: =IFERROR(SUMIF(لاگ_فاکتور!$I$3:$I$1622,A21,لاگ_فاکتور!$L$3:$L$1622),0) -> 0 | K21: =MAX(0,I21-J21) -> 9 | L21: =IF(C21="","",IF(K21<=0,"🔴 تمام",IF(K21<=تنظیمات_سیستم!$C$7,"🟠 کم","🟢 OK"))) -> 🟢 OK
A22: =IF(C22="","","SKU-"&TEXT(ROW()-3,"0000")) -> SKU-0019 | B22: CHSMSYHPT1 | C22: شومیز گیپور زرد فری | D22: شومیز | E22: Cotton | F22: Spring/Summer | H22: 1080000 | I22: 9 | J22: =IFERROR(SUMIF(لاگ_فاکتور!$I$3:$I$1622,A22,لاگ_فاکتور!$L$3:$L$1622),0) -> 0 | K22: =MAX(0,I22-J22) -> 9 | L22: =IF(C22="","",IF(K22<=0,"🔴 تمام",IF(K22<=تنظیمات_سیستم!$C$7,"🟠 کم","🟢 OK"))) -> 🟢 OK
A23: =IF(C23="","","SKU-"&TEXT(ROW()-3,"0000")) -> SKU-0020 | B23: CHSMSYHPT2 | C23: شومیز گیپور طوسی فری | D23: شومیز | E23: Cotton | F23: Spring/Summer | H23: 1080000 | I23: 9 | J23: =IFERROR(SUMIF(لاگ_فاکتور!$I$3:$I$1622,A23,لاگ_فاکتور!$L$3:$L$1622),0) -> 0 | K23: =MAX(0,I23-J23) -> 9 | L23: =IF(C23="","",IF(K23<=0,"🔴 تمام",IF(K23<=تنظیمات_سیستم!$C$7,"🟠 کم","🟢 OK"))) -> 🟢 OK
A24: =IF(C24="","","SKU-"&TEXT(ROW()-3,"0000")) -> SKU-0021 | B24: CHSMGPRYLFR | C24: شومیز گیپور آبی فری | D24: شومیز | E24: Cotton | F24: Spring/Summer | H24: 1080000 | I24: 9 | J24: =IFERROR(SUMIF(لاگ_فاکتور!$I$3:$I$1622,A24,لاگ_فاکتور!$L$3:$L$1622),0) -> 0 | K24: =MAX(0,I24-J24) -> 9 | L24: =IF(C24="","",IF(K24<=0,"🔴 تمام",IF(K24<=تنظیمات_سیستم!$C$7,"🟠 کم","🟢 OK"))) -> 🟢 OK
A25: =IF(C25="","","SKU-"&TEXT(ROW()-3,"0000")) -> SKU-0022 | B25: CHSMGPRGRFR | C25: شومیز گیپور صورتی فری | D25: شومیز | E25: Cotton | F25: Spring/Summer | H25: 1080000 | I25: 9 | J25: =IFERROR(SUMIF(لاگ_فاکتور!$I$3:$I$1622,A25,لاگ_فاکتور!$L$3:$L$1622),0) -> 0 | K25: =MAX(0,I25-J25) -> 9 | L25: =IF(C25="","",IF(K25<=0,"🔴 تمام",IF(K25<=تنظیمات_سیستم!$C$7,"🟠 کم","🟢 OK"))) -> 🟢 OK
... A86: =IF(C86="","","SKU-"&TEXT(ROW()-3,"0000")) -> SKU-0083 | B86: CHSHKTRMU3 | C86: شلوار کاترین نسکافه ای3 | D86: شلوار | E86: Crepe | F86: All-Season | H86: 4580000 | I86: 9 | J86: =IFERROR(SUMIF(لاگ_فاکتور!$I$3:$I$1622,A86,لاگ_فاکتور!$L$3:$L$1622),0) -> 0 | K86: =MAX(0,I86-J86) -> 9 | L86: =IF(C86="","",IF(K86<=0,"🔴 تمام",IF(K86<=تنظیمات_سیستم!$C$7,"🟠 کم","🟢 OK"))) -> 🟢 OK
A87: =IF(C87="","","SKU-"&TEXT(ROW()-3,"0000")) -> SKU-0084 | C87: شلوار کاترین نوک مدادی 1 | D87: شلوار | E87: Crepe | F87: All-Season | H87: 4580000 | I87: 9 | J87: =IFERROR(SUMIF(لاگ_فاکتور!$I$3:$I$1622,A87,لاگ_فاکتور!$L$3:$L$1622),0) -> 0 | K87: =MAX(0,I87-J87) -> 9 | L87: =IF(C87="","",IF(K87<=0,"🔴 تمام",IF(K87<=تنظیمات_سیستم!$C$7,"🟠 کم","🟢 OK"))) -> 🟢 OK
A88: =IF(C88="","","SKU-"&TEXT(ROW()-3,"0000")) -> SKU-0085 | B88: CHSHKTRCH3 | C88: شلوار کاترین نوک مدادی 2 | D88: شلوار | E88: Crepe | F88: All-Season | H88: 4580000 | I88: 9 | J88: =IFERROR(SUMIF(لاگ_فاکتور!$I$3:$I$1622,A88,لاگ_فاکتور!$L$3:$L$1622),0) -> 0 | K88: =MAX(0,I88-J88) -> 9 | L88: =IF(C88="","",IF(K88<=0,"🔴 تمام",IF(K88<=تنظیمات_سیستم!$C$7,"🟠 کم","🟢 OK"))) -> 🟢 OK
A89: =IF(C89="","","SKU-"&TEXT(ROW()-3,"0000")) -> SKU-0086 | B89: CHSHKTRIV1 | C89: شلوار کاترین نوک مدادی3 | D89: شلوار | E89: Crepe | F89: All-Season | H89: 4580000 | I89: 9 | J89: =IFERROR(SUMIF(لاگ_فاکتور!$I$3:$I$1622,A89,لاگ_فاکتور!$L$3:$L$1622),0) -> 0 | K89: =MAX(0,I89-J89) -> 9 | L89: =IF(C89="","",IF(K89<=0,"🔴 تمام",IF(K89<=تنظیمات_سیستم!$C$7,"🟠 کم","🟢 OK"))) -> 🟢 OK
A90: =IF(C90="","","SKU-"&TEXT(ROW()-3,"0000")) -> SKU-0087 | B90: CHSHKTRCH1 | C90: شلوار کاترین استخوانی 1 | D90: شلوار | E90: Crepe | F90: All-Season | H90: 4580000 | I90: 9 | J90: =IFERROR(SUMIF(لاگ_فاکتور!$I$3:$I$1622,A90,لاگ_فاکتور!$L$3:$L$1622),0) -> 0 | K90: =MAX(0,I90-J90) -> 9 | L90: =IF(C90="","",IF(K90<=0,"🔴 تمام",IF(K90<=تنظیمات_سیستم!$C$7,"🟠 کم","🟢 OK"))) -> 🟢 OK
A91: =IF(C91="","","SKU-"&TEXT(ROW()-3,"0000")) -> SKU-0088 | B91: CHSHKTRCH2 | C91: شلوار کاترین استخوانی2 | D91: شلوار | E91: Crepe | F91: All-Season | H91: 4580000 | I91: 9 | J91: =IFERROR(SUMIF(لاگ_فاکتور!$I$3:$I$1622,A91,لاگ_فاکتور!$L$3:$L$1622),0) -> 0 | K91: =MAX(0,I91-J91) -> 9 | L91: =IF(C91="","",IF(K91<=0,"🔴 تمام",IF(K91<=تنظیمات_سیستم!$C$7,"🟠 کم","🟢 OK"))) -> 🟢 OK
A92: =IF(C92="","","SKU-"&TEXT(ROW()-3,"0000")) -> SKU-0089 | B92: CHSHKTRCO2 | C92: شلوار کاترین استخوانی3 | D92: شلوار | E92: Crepe | F92: All-Season | H92: 4580000 | I92: 9 | J92: =IFERROR(SUMIF(لاگ_فاکتور!$I$3:$I$1622,A92,لاگ_فاکتور!$L$3:$L$1622),0) -> 0 | K92: =MAX(0,I92-J92) -> 9 | L92: =IF(C92="","",IF(K92<=0,"🔴 تمام",IF(K92<=تنظیمات_سیستم!$C$7,"🟠 کم","🟢 OK"))) -> 🟢 OK
A93: =IF(C93="","","SKU-"&TEXT(ROW()-3,"0000")) -> SKU-0090 | B93: CHSHKTRBK2 | C93: شومیز تایملس سبز فری | D93: شومیز | E93: Silk | F93: All-Season | H93: 2680000 | I93: 9 | J93: =IFERROR(SUMIF(لاگ_فاکتور!$I$3:$I$1622,A93,لاگ_فاکتور!$L$3:$L$1622),0) -> 0 | K93: =MAX(0,I93-J93) -> 9 | L93: =IF(C93="","",IF(K93<=0,"🔴 تمام",IF(K93<=تنظیمات_سیستم!$C$7,"🟠 کم","🟢 OK"))) -> 🟢 OK
A94: =IF(C94="","","SKU-"&TEXT(ROW()-3,"0000")) -> SKU-0091 | B94: CHSMLIVWH1 | C94: شومیز تایملس مشکی فری | D94: شومیز | E94: Silk | F94: All-Season | H94: 2680000 | I94: 9 | J94: =IFERROR(SUMIF(لاگ_فاکتور!$I$3:$I$1622,A94,لاگ_فاکتور!$L$3:$L$1622),0) -> 0 | K94: =MAX(0,I94-J94) -> 9 | L94: =IF(C94="","",IF(K94<=0,"🔴 تمام",IF(K94<=تنظیمات_سیستم!$C$7,"🟠 کم","🟢 OK"))) -> 🟢 OK
A95: =IF(C95="","","SKU-"&TEXT(ROW()-3,"0000")) -> SKU-0092 | B95: CHSMDRYBK1 | C95: شومیز لینن سونای سفید1 | D95: شومیز | E95: linen | F95: Spring/Summer | H95: 3780000 | I95: 9 | J95: =IFERROR(SUMIF(لاگ_فاکتور!$I$3:$I$1622,A95,لاگ_فاکتور!$L$3:$L$1622),0) -> 0 | K95: =MAX(0,I95-J95) -> 9 | L95: =IF(C95="","",IF(K95<=0,"🔴 تمام",IF(K95<=تنظیمات_سیستم!$C$7,"🟠 کم","🟢 OK"))) -> 🟢 OK
A96: =IF(C96="","","SKU-"&TEXT(ROW()-3,"0000")) -> SKU-0093 | B96: CHSMDRYBK2 | C96: شومیز لینن سونای سفید2 | D96: شومیز | E96: linen | F96: Spring/Summer | H96: 3780000 | I96: 9 | J96: =IFERROR(SUMIF(لاگ_فاکتور!$I$3:$I$1622,A96,لاگ_فاکتور!$L$3:$L$1622),0) -> 0 | K96: =MAX(0,I96-J96) -> 9 | L96: =IF(C96="","",IF(K96<=0,"🔴 تمام",IF(K96<=تنظیمات_سیستم!$C$7,"🟠 کم","🟢 OK"))) -> 🟢 OK
A97: =IF(C97="","","SKU-"&TEXT(ROW()-3,"0000")) -> SKU-0094 | B97: CHSMDRYCR1 | C97: شومیز لینن سونای مشکی 1 | D97: شومیز | E97: linen | F97: Spring/Summer | H97: 3780000 | I97: 9 | J97: =IFERROR(SUMIF(لاگ_فاکتور!$I$3:$I$1622,A97,لاگ_فاکتور!$L$3:$L$1622),0) -> 0 | K97: =MAX(0,I97-J97) -> 9 | L97: =IF(C97="","",IF(K97<=0,"🔴 تمام",IF(K97<=تنظیمات_سیستم!$C$7,"🟠 کم","🟢 OK"))) -> 🟢 OK
A98: =IF(C98="","","SKU-"&TEXT(ROW()-3,"0000")) -> SKU-0095 | B98: CHSMDRYCR2 | C98: شومیز لینن سونای مشکی2 | D98: شومیز | E98: linen | F98: Spring/Summer | H98: 3780000 | I98: 9 | J98: =IFERROR(SUMIF(لاگ_فاکتور!$I$3:$I$1622,A98,لاگ_فاکتور!$L$3:$L$1622),0) -> 0 | K98: =MAX(0,I98-J98) -> 9 | L98: =IF(C98="","",IF(K98<=0,"🔴 تمام",IF(K98<=تنظیمات_سیستم!$C$7,"🟠 کم","🟢 OK"))) -> 🟢 OK
A99: =IF(C99="","","SKU-"&TEXT(ROW()-3,"0000")) -> SKU-0096 | B99: CHSMDRYCT1 | C99: شومیز لینن سونای سرمه ای 1 | D99: شومیز | E99: linen | F99: Spring/Summer | H99: 3780000 | I99: 9 | J99: =IFERROR(SUMIF(لاگ_فاکتور!$I$3:$I$1622,A99,لاگ_فاکتور!$L$3:$L$1622),0) -> 0 | K99: =MAX(0,I99-J99) -> 9 | L99: =IF(C99="","",IF(K99<=0,"🔴 تمام",IF(K99<=تنظیمات_سیستم!$C$7,"🟠 کم","🟢 OK"))) -> 🟢 OK
... A109: =IF(C109="","","SKU-"&TEXT(ROW()-3,"0000")) -> SKU-0106 | B109: CHSMLSNWH2 | C109: شلوار پنتر 2 | D109: شلوار | E109: Crepe | F109: Spring/Summer | H109: 1680000 | I109: 9 | J109: =IFERROR(SUMIF(لاگ_فاکتور!$I$3:$I$1622,A109,لاگ_فاکتور!$L$3:$L$1622),0) -> 0 | K109: =MAX(0,I109-J109) -> 9 | L109: =IF(C109="","",IF(K109<=0,"🔴 تمام",IF(K109<=تنظیمات_سیستم!$C$7,"🟠 کم","🟢 OK"))) -> 🟢 OK
A110: =IF(C110="","","SKU-"&TEXT(ROW()-3,"0000")) -> SKU-0107 | B110: CHSHPNY--2 | C110: شلوار مانا کله غازی1 | D110: شلوار | E110: Linen | F110: Spring/Summer | I110: 9 | J110: =IFERROR(SUMIF(لاگ_فاکتور!$I$3:$I$1622,A110,لاگ_فاکتور!$L$3:$L$1622),0) -> 0 | K110: =MAX(0,I110-J110) -> 9 | L110: =IF(C110="","",IF(K110<=0,"🔴 تمام",IF(K110<=تنظیمات_سیستم!$C$7,"🟠 کم","🟢 OK"))) -> 🟢 OK
...

Sheet KPI_روزانه
A2: KPIروزانه فروشگاه
A3: سلول‌های زرد = ورود دستی | سلول‌های آبی‌تیره = فرمول خودکار از لاگ فاکتور
A4: تاریخ Date | B4: کد پرسنل Staff_ID | C4: نام پرسنل Name | D4: ورودی مشتری Footfall | E4: اتاق پرو Fitting_Room | F4: تعداد فاکتور Invoices | G4: فروش (تومان) Sales | H4: تخفیف داده Discounts | I4: مرجوعی Returns | J4: اپ‌سل موفق Upsell | K4: نرخ تبدیل% Conv_Rate | L4: ATV (میانگین فاکتور) | M4: UPT (میانگین اقلام) | N4: شکایت Complaints | O4: رویداد روز Events | P4: یادداشت مدیر Mgr_Notes
A5: 1405/07/01 | B5: 0 | C5: =IFERROR(INDEX(اطلاعات_پرسنل!$D$4:$D$59,MATCH(B5,اطلاعات_پرسنل!$A$4:$A$59,0)),"") -> فروشگاه | D5: 4 | E5: 1 | F5: =IFERROR(SUMIFS(لاگ_فاکتور!$V$3:$V$1622,لاگ_فاکتور!$B$3:$B$1622,A5,لاگ_فاکتور!$C$3:$C$1622,B5),0) -> 1 | G5: =IFERROR(SUMIFS(لاگ_فاکتور!$O$3:$O$1622,لاگ_فاکتور!$B$3:$B$1622,A5,لاگ_فاکتور!$C$3:$C$1622,B5),0) -> 2000000 | H5: =IFERROR(SUMIFS(لاگ_فاکتور!$N$3:$N$1622,لاگ_فاکتور!$B$3:$B$1622,A5,لاگ_فاکتور!$C$3:$C$1622,B5),0) -> 0 | I5: 0 | J5: 0 | K5: =IFERROR(F5/D5,0) -> 0.25 | L5: =IFERROR(G5/F5,0) -> 2000000 | M5: =IFERROR(SUMIFS(لاگ_فاکتور!$L$3:$L$1622,لاگ_فاکتور!$B$3:$B$1622,A5,لاگ_فاکتور!$C$3:$C$1622,B5)/F5,0) -> 1 | N5: 0
A6: 1405/07/01 | B6: 1 | C6: =IFERROR(INDEX(اطلاعات_پرسنل!$D$4:$D$59,MATCH(B6,اطلاعات_پرسنل!$A$4:$A$59,0)),"") -> دریا کریمی | D6: 4 | F6: =IFERROR(SUMIFS(لاگ_فاکتور!$V$3:$V$1622,لاگ_فاکتور!$B$3:$B$1622,A6,لاگ_فاکتور!$C$3:$C$1622,B6),0) -> 0 | G6: =IFERROR(SUMIFS(لاگ_فاکتور!$O$3:$O$1622,لاگ_فاکتور!$B$3:$B$1622,A6,لاگ_فاکتور!$C$3:$C$1622,B6),0) -> 0 | H6: =IFERROR(SUMIFS(لاگ_فاکتور!$N$3:$N$1622,لاگ_فاکتور!$B$3:$B$1622,A6,لاگ_فاکتور!$C$3:$C$1622,B6),0) -> 0 | I6: 0 | J6: 0 | K6: =IFERROR(F6/D6,0) -> 0 | L6: =IFERROR(G6/F6,0) -> 0 | M6: =IFERROR(SUMIFS(لاگ_فاکتور!$L$3:$L$1622,لاگ_فاکتور!$B$3:$B$1622,A6,لاگ_فاکتور!$C$3:$C$1622,B6)/F6,0) -> 0 | N6: 0
A7: 1405/07/01 | B7: 2 | C7: =IFERROR(INDEX(اطلاعات_پرسنل!$D$4:$D$59,MATCH(B7,اطلاعات_پرسنل!$A$4:$A$59,0)),"") -> ماحی حمیدپور | D7: 2 | F7: =IFERROR(SUMIFS(لاگ_فاکتور!$V$3:$V$1622,لاگ_فاکتور!$B$3:$B$1622,A7,لاگ_فاکتور!$C$3:$C$1622,B7),0) -> 0 | G7: =IFERROR(SUMIFS(لاگ_فاکتور!$O$3:$O$1622,لاگ_فاکتور!$B$3:$B$1622,A7,لاگ_فاکتور!$C$3:$C$1622,B7),0) -> 0 | H7: =IFERROR(SUMIFS(لاگ_فاکتور!$N$3:$N$1622,لاگ_فاکتور!$B$3:$B$1622,A7,لاگ_فاکتور!$C$3:$C$1622,B7),0) -> 0 | I7: 0 | J7: 0 | K7: =IFERROR(F7/D7,0) -> 0 | L7: =IFERROR(G7/F7,0) -> 0 | M7: =IFERROR(SUMIFS(لاگ_فاکتور!$L$3:$L$1622,لاگ_فاکتور!$B$3:$B$1622,A7,لاگ_فاکتور!$C$3:$C$1622,B7)/F7,0) -> 0 | N7: 0
